Workbook

Sheet 0_ReadMe
A1: Agroforestry Quantification – Workbook Overview
A2: This workbook implements the ex-ante quantification of greenhouse gas removals from the agroforestry component of a Verra VM0042 Improved Agricultural Land Management project, using a modeled QA1 approach consistent with CDM AR-TOOL14. Workbook structure: • Tab 2 – Activity Data: Agroforestry area, species composition, spacing, and tree density inputs. • Tab 3 – Growth Inputs: Species-specific DBH and height growth trajectories and allometric equations. • Tab 4 – Biomass per ha: Conversion of per-tree biomass to per-hectare biomass, including live and dead pools. • Tab 5 – ER Results: Annual biomass CO₂e stocks and emission reductions aggregated across species and area. • Tab 6 – Literature & Citations: Sources for growth assumptions, allometric equations, and parameters. Methodological cross-references: • Verra VM0042 v2.2: QA1 modeled approach; agroforestry as eligible activity (Appendix 1); carbon stock-change accounting for biomass pools. • CDM AR-TOOL14 v4.1: Ex-ante estimation using growth models (Section 5) and biomass estimation using allometric equations and root-to-shoot ratios for BGB (Section 6).

Sheet 1_PlantingPlan
A1: Species | B1: Area (ha) | C1: Planting method | D1: Spacing in meters | E1: Suggested density (trees/ha) | F1: Total trees | G1: Actual density (trees/ha) | H1: Key conservative assumptions (agroforestry module)
A2: Cashew | B2: 4444.4444 | C2: Alley | D2: 10x10 | E2: 100 | F2: 311111.11 | G2: 70 | H2: • Baseline tree biomass on farms assumed = 0 (no pre-existing agroforestry trees credited).
A3: Dawadawa | B3: 222.22222 | C3: Alley | D3: 10x10 | E3: 100 | F3: 15555.556 | G3: 70 | H3: • All trees assumed planted in Year 1 (single cohort) unless revised in the PDD activity data section.
A4: Mango | B4: 1111.1111 | C4: Alley | D4: 10x10 | E4: 100 | F4: 87777.778 | G4: 79 | H4: • Species-specific survival curves applied; no late-period artificial survival declines.
A5: Moringa | B5: 1111.1111 | C5: Alley | D5: 10x10 | E5: 100 | F5: 87777.778 | G5: 79 | H5: • BGB included via AR-TOOL14 root-to-shoot relationships; no additional soil carbon credited in this module.
A6: Shea | B6: 1111.1111 | C6: Alley | D6: 10x10 | E6: 100 | F6: 87777.778 | G6: 79 | H6: • Retained dead biomass pool included; dead biomass decays at a conservative first-order rate (k_dead).
H7: • Carbon fraction fixed at 0.47 and CO2 conversion uses 44/12.
A10: Key Conservative Assumptions – Agroforestry Quantification
A11: • Baseline tree biomass on agricultural land assumed to be zero.
A12: • All agroforestry trees assumed planted in Year 1 (single cohort).
A13: • Species-specific survival curves applied; no artificial late-period survival declines.
A14: • Above-ground biomass, below-ground biomass, and retained dead biomass included; soil carbon, litter, and harvested wood products excluded.
A15: • Below-ground biomass estimated using AR-TOOL14 root-to-shoot relationships.
A16: • Dead biomass retained and decayed conservatively using first-order decay.
A17: • Carbon fraction fixed at 0.47; CO₂ conversion uses 44/12.
A18: • All growth parameters anchored to peer-reviewed or authoritative literature.

Sheet 2_Assumptions
A1: Parameter | B1: Value | C1: Units | D1: Notes
A2: CF_tree | B2: 0.47 | C2: t C / t d.m. | D2: Carbon fraction of dry biomass (AR-TOOL14 default).
A3: CO2_per_C | B3: 3.6666667 | C3: t CO2 / t C | D3: Convert carbon to CO2.
A4: RootShoot_Rj | B4: Rj = EXP(-1.085 + 0.9256*LN(b)) / b | C4: dimensionless | D4: Root:shoot ratio from AR-TOOL14 (b=AGB t d.m./ha).
A5: Crediting_horizon | B5: 40 | C5: years | D5: Model horizon.
A6: Allometry | B6: Chave2014: AGB=0.0673*(rho*D^2*H)^0.976 | C6: kg d.m./tree | D6: rho g/cm3, D cm, H m.

Sheet 3_GrowthInputs
A1: Species | B1: Year (t) | C1: DBH (cm) | D1: Height (m) | E1: rho (g/cm3) | F1: AGB per tree (kg d.m./tree) | G1: Key
A2: Cashew | B2: 1 | C2: 1.75 | D2: 0.75 | E2: 0.5 | G2: =A2&"|"&B2 -> Cashew|1
A3: Cashew | B3: 2 | C3: 2.089 | D3: 0.923 | E3: 0.5 | F3: =IF(OR(C3="",D3=""),NA(),0.076*POWER(POWER(C3,2)*D3,0.927)) -> 0.27651675 | G3: =A3&"|"&B3 -> Cashew|2
A4: Cashew | B4: 3 | C4: 2.487 | D4: 1.132 | E4: 0.5 | F4: =IF(OR(C4="",D4=""),NA(),0.076*POWER(POWER(C4,2)*D4,0.927)) -> 0.46164925 | G4: =A4&"|"&B4 -> Cashew|3
A5: Cashew | B5: 4 | C5: 2.951 | D5: 1.38 | E5: 0.5 | F5: =IF(OR(C5="",D5=""),NA(),0.076*POWER(POWER(C5,2)*D5,0.927)) -> 0.76173589 | G5: =A5&"|"&B5 -> Cashew|4
A6: Cashew | B6: 5 | C6: 3.488 | D6: 1.673 | E6: 0.5 | F6: =IF(OR(C6="",D6=""),NA(),0.076*POWER(POWER(C6,2)*D6,0.927)) -> 1.2414554 | G6: =A6&"|"&B6 -> Cashew|5
A7: Cashew | B7: 6 | C7: 4.105 | D7: 2.013 | E7: 0.5 | F7: =IF(OR(C7="",D7=""),NA(),0.076*POWER(POWER(C7,2)*D7,0.927)) -> 1.993239 | G7: =A7&"|"&B7 -> Cashew|6
A8: Cashew | B8: 7 | C8: 4.806 | D8: 2.402 | E8: 0.5 | F8: =IF(OR(C8="",D8=""),NA(),0.076*POWER(POWER(C8,2)*D8,0.927)) -> 3.1450812 | G8: =A8&"|"&B8 -> Cashew|7
A9: Cashew | B9: 8 | C9: 5.595 | D9: 2.84 | E9: 0.5 | F9: =IF(OR(C9="",D9=""),NA(),0.076*POWER(POWER(C9,2)*D9,0.927)) -> 4.8692387 | G9: =A9&"|"&B9 -> Cashew|8
A10: Cashew | B10: 9 | C10: 6.472 | D10: 3.323 | E10: 0.5 | F10: =IF(OR(C10="",D10=""),NA(),0.076*POWER(POWER(C10,2)*D10,0.927)) -> 7.3779824 | G10: =A10&"|"&B10 -> Cashew|9
A11: Cashew | B11: 10 | C11: 7.434 | D11: 3.844 | E11: 0.5 | F11: =IF(OR(C11="",D11=""),NA(),0.076*POWER(POWER(C11,2)*D11,0.927)) -> 10.918284 | G11: =A11&"|"&B11 -> Cashew|10
A12: Cashew | B12: 11 | C12: 8.473 | D12: 4.393 | E12: 0.5 | F12: =IF(OR(C12="",D12=""),NA(),0.076*POWER(POWER(C12,2)*D12,0.927)) -> 15.748319 | G12: =A12&"|"&B12 -> Cashew|11
A13: Cashew | B13: 12 | C13: 9.578 | D13: 4.957 | E13: 0.5 | F13: =IF(OR(C13="",D13=""),NA(),0.076*POWER(POWER(C13,2)*D13,0.927)) -> 22.108795 | G13: =A13&"|"&B13 -> Cashew|12
A14: Cashew | B14: 13 | C14: 10.734 | D14: 5.522 | E14: 0.5 | F14: =IF(OR(C14="",D14=""),NA(),0.076*POWER(POWER(C14,2)*D14,0.927)) -> 30.183455 | G14: =A14&"|"&B14 -> Cashew|13
... A41: Cashew | B41: 40 | C41: 24.814 | D41: 9.982 | E41: 0.5 | F41: =IF(OR(C41="",D41=""),NA(),0.076*POWER(POWER(C41,2)*D41,0.927)) -> 247.09053 | G41: =A41&"|"&B41 -> Cashew|40
A42: Dawadawa | B42: 1 | C42: 1.2 | D42: 1 | E42: 0.6 | F42: =IF(OR(E42="",C42="",D42=""),NA(),0.0673*POWER(E42*POWER(C42,2)*D42,0.976)) -> 0.058351561 | G42: =A42&"|"&B42 -> Dawadawa|1
A43: Dawadawa | B43: 2 | C43: 2.4 | D43: 1.557 | E43: 0.6 | F43: =IF(OR(E43="",C43="",D43=""),NA(),0.0673*POWER(E43*POWER(C43,2)*D43,0.976)) -> 0.34780572 | G43: =A43&"|"&B43 -> Dawadawa|2
A44: Dawadawa | B44: 3 | C44: 3.6 | D44: 2.382 | E44: 0.6 | F44: =IF(OR(E44="",C44="",D44=""),NA(),0.0673*POWER(E44*POWER(C44,2)*D44,0.976)) -> 1.1622199 | G44: =A44&"|"&B44 -> Dawadawa|3
A45: Dawadawa | B45: 4 | C45: 4.8 | D45: 3.548 | E45: 0.6 | F45: =IF(OR(E45="",C45="",D45=""),NA(),0.0673*POWER(E45*POWER(C45,2)*D45,0.976)) -> 3.0064749 | G45: =A45&"|"&B45 -> Dawadawa|4
A46: Dawadawa | B46: 5 | C46: 6 | D46: 5.099 | E46: 0.6 | F46: =IF(OR(E46="",C46="",D46=""),NA(),0.0673*POWER(E46*POWER(C46,2)*D46,0.976)) -> 6.6213615 | G46: =A46&"|"&B46 -> Dawadawa|5
A47: Dawadawa | B47: 6 | C47: 7.2 | D47: 7 | E47: 0.6 | F47: =IF(OR(E47="",C47="",D47=""),NA(),0.0673*POWER(E47*POWER(C47,2)*D47,0.976)) -> 12.87714 | G47: =A47&"|"&B47 -> Dawadawa|6
A48: Dawadawa | B48: 7 | C48: 8.4 | D48: 9.109 | E48: 0.6 | F48: =IF(OR(E48="",C48="",D48=""),NA(),0.0673*POWER(E48*POWER(C48,2)*D48,0.976)) -> 22.497137 | G48: =A48&"|"&B48 -> Dawadawa|7
A49: Dawadawa | B49: 8 | C49: 9.6 | D49: 11.206 | E49: 0.6 | F49: =IF(OR(E49="",C49="",D49=""),NA(),0.0673*POWER(E49*POWER(C49,2)*D49,0.976)) -> 35.739456 | G49: =A49&"|"&B49 -> Dawadawa|8
A50: Dawadawa | B50: 9 | C50: 10.8 | D50: 13.076 | E50: 0.6 | F50: =IF(OR(E50="",C50="",D50=""),NA(),0.0673*POWER(E50*POWER(C50,2)*D50,0.976)) -> 52.289365 | G50: =A50&"|"&B50 -> Dawadawa|9
A51: Dawadawa | B51: 10 | C51: 12 | D51: 14.588 | E51: 0.6 | F51: =IF(OR(E51="",C51="",D51=""),NA(),0.0673*POWER(E51*POWER(C51,2)*D51,0.976)) -> 71.468116 | G51: =A51&"|"&B51 -> Dawadawa|10
A52: Dawadawa | B52: 11 | C52: 13.2 | D52: 15.717 | E52: 0.6 | F52: =IF(OR(E52="",C52="",D52=""),NA(),0.0673*POWER(E52*POWER(C52,2)*D52,0.976)) -> 92.577997 | G52: =A52&"|"&B52 -> Dawadawa|11
A53: Dawadawa | B53: 12 | C53: 14.4 | D53: 16.51 | E53: 0.6 | F53: =IF(OR(E53="",C53="",D53=""),NA(),0.0673*POWER(E53*POWER(C53,2)*D53,0.976)) -> 115.11593 | G53: =A53&"|"&B53 -> Dawadawa|12
... A81: Dawadawa | B81: 40 | C81: 48 | D81: 18 | E81: 0.6 | F81: =IF(OR(E81="",C81="",D81=""),NA(),0.0673*POWER(E81*POWER(C81,2)*D81,0.976)) -> 1313.4681 | G81: =A81&"|"&B81 -> Dawadawa|40
A82: Mango | B82: 1 | C82: 3.673 | D82: 1.519 | E82: 0.6 | F82: =IF(C82<=0,NA(),EXP(-2.43+2.51*LN(C82))) -> 2.3060405 | G82: =A82&"|"&B82 -> Mango|1
A83: Mango | B83: 2 | C83: 4.26 | D83: 1.73 | E83: 0.6 | F83: =IF(C83<=0,NA(),EXP(-2.43+2.51*LN(C83))) -> 3.3456654 | G83: =A83&"|"&B83 -> Mango|2
A84: Mango | B84: 3 | C84: 4.935 | D84: 1.966 | E84: 0.6 | F84: =IF(C84<=0,NA(),EXP(-2.43+2.51*LN(C84))) -> 4.8396636 | G84: =A84&"|"&B84 -> Mango|3
A85: Mango | B85: 4 | C85: 5.708 | D85: 2.23 | E85: 0.6 | F85: =IF(C85<=0,NA(),EXP(-2.43+2.51*LN(C85))) -> 6.973313 | G85: =A85&"|"&B85 -> Mango|4
A86: Mango | B86: 5 | C86: 6.593 | D86: 2.522 | E86: 0.6 | F86: =IF(C86<=0,NA(),EXP(-2.43+2.51*LN(C86))) -> 10.01297 | G86: =A86&"|"&B86 -> Mango|5
A87: Mango | B87: 6 | C87: 7.6 | D87: 2.845 | E87: 0.6 | F87: =IF(C87<=0,NA(),EXP(-2.43+2.51*LN(C87))) -> 14.305615 | G87: =A87&"|"&B87 -> Mango|6
A88: Mango | B88: 7 | C88: 8.742 | D88: 3.2 | E88: 0.6 | F88: =IF(C88<=0,NA(),EXP(-2.43+2.51*LN(C88))) -> 20.328602 | G88: =A88&"|"&B88 -> Mango|7
A89: Mango | B89: 8 | C89: 10.033 | D89: 3.586 | E89: 0.6 | F89: =IF(C89<=0,NA(),EXP(-2.43+2.51*LN(C89))) -> 28.724716 | G89: =A89&"|"&B89 -> Mango|8
A90: Mango | B90: 9 | C90: 11.483 | D90: 4.005 | E90: 0.6 | F90: =IF(C90<=0,NA(),EXP(-2.43+2.51*LN(C90))) -> 40.309125 | G90: =A90&"|"&B90 -> Mango|9
A91: Mango | B91: 10 | C91: 13.104 | D91: 4.455 | E91: 0.6 | F91: =IF(C91<=0,NA(),EXP(-2.43+2.51*LN(C91))) -> 56.149793 | G91: =A91&"|"&B91 -> Mango|10
A92: Mango | B92: 11 | C92: 14.904 | D92: 4.935 | E92: 0.6 | F92: =IF(C92<=0,NA(),EXP(-2.43+2.51*LN(C92))) -> 77.56299 | G92: =A92&"|"&B92 -> Mango|11
A93: Mango | B93: 12 | C93: 16.889 | D93: 5.442 | E93: 0.6 | F93: =IF(C93<=0,NA(),EXP(-2.43+2.51*LN(C93))) -> 106.1574 | G93: =A93&"|"&B93 -> Mango|12
...

Sheet 4_BiomassPerHa
A1: Species | B1: Year (t) | C1: Trees planted/ha | D1: Survival S(t) | E1: Trees alive/ha | F1: AGB/tree (kg) | G1: AGB/ha (t d.m./ha) | H1: Rj | I1: BGB/ha (t d.m./ha) | J1: Total biomass/ha (t d.m./ha) | K1: CO2e stock/ha (t CO2e/ha) | M1: Species | N1: Trees/ha | O1: S1 | P1: Sa | Q1: Key | S1: Species_param | T1: S1 (Yr1) | U1: Sa_est (Yr2-3) | V1: Sa_mid (Yr4-20) | W1: Sa_late (Yr21+) | Y1: Dead biomass pool/ha (t d.m./ha) | Z1: Total biomass incl. dead/ha (t d.m./ha) | AB1: k_dead (yr-1)
A2: Cashew | B2: 1 | C2: =INDEX($N$2:$N$6, MATCH(A2, $M$2:$M$6, 0)) -> 70 | D2: =IF(B2=1,INDEX($T$2:$T$6, MATCH(A2, $S$2:$S$6, 0)),INDEX($T$2:$T$6, MATCH(A2, $S$2:$S$6, 0))*POWER(INDEX($U$2:$U$6, MATCH(A2, $S$2:$S$6, 0)),MIN(B2-1,2))*POWER(INDEX($V$2:$V$6, MATCH(A2, $S$2:$S$6, 0)),MAX(MIN(B2-3,17),0))*POWER(INDEX($W$2:$W$6, MATCH(A2, $S$2:$S$6, 0)),MAX(B2-20,0))) -> 0.75 | E2: =C2*D2 -> 52.5 | F2: =IFERROR(INDEX('3_GrowthInputs'!$F$2:$F$201, MATCH(Q2, '3_GrowthInputs'!$G$2:$G$201, 0)), NA()) -> 0 | G2: =IF(OR(ISNA(E2),ISNA(F2)),NA(),E2*F2/1000) -> 0 | H2: =IF(ISNA(G2),NA(),IF(G2>0,EXP(-1.085+0.9256*LN(G2))/G2,0)) -> 0 | I2: =IF(OR(ISNA(G2),ISNA(H2)),NA(),G2*H2) -> 0 | J2: =IF(OR(ISNA(G2),ISNA(I2)),NA(),G2+I2) -> 0 | K2: =Z2*0.47*(44/12) -> 0 | M2: Cashew | N2: 70 | O2: 0.7 | P2: 0.95 | Q2: =A2&"|"&B2 -> Cashew|1 | S2: Cashew | T2: 0.75 | U2: 0.95 | V2: 0.99 | W2: 0.985 | Y2: 0 | Z2: =J2+Y2 -> 0 | AB2: 0.1
A3: Cashew | B3: 2 | C3: =INDEX($N$2:$N$6, MATCH(A3, $M$2:$M$6, 0)) -> 70 | D3: =IF(B3=1,INDEX($T$2:$T$6, MATCH(A3, $S$2:$S$6, 0)),INDEX($T$2:$T$6, MATCH(A3, $S$2:$S$6, 0))*POWER(INDEX($U$2:$U$6, MATCH(A3, $S$2:$S$6, 0)),MIN(B3-1,2))*POWER(INDEX($V$2:$V$6, MATCH(A3, $S$2:$S$6, 0)),MAX(MIN(B3-3,17),0))*POWER(INDEX($W$2:$W$6, MATCH(A3, $S$2:$S$6, 0)),MAX(B3-20,0))) -> 0.7125 | E3: =C3*D3 -> 49.875 | F3: =IFERROR(INDEX('3_GrowthInputs'!$F$2:$F$201, MATCH(Q3, '3_GrowthInputs'!$G$2:$G$201, 0)), NA()) -> 0.27651675 | G3: =IF(OR(ISNA(E3),ISNA(F3)),NA(),E3*F3/1000) -> 0.013791273 | H3: =IF(ISNA(G3),NA(),IF(G3>0,EXP(-1.085+0.9256*LN(G3))/G3,0)) -> 0.46473344 | I3: =IF(OR(ISNA(G3),ISNA(H3)),NA(),G3*H3) -> 0.0064092656 | J3: =IF(OR(ISNA(G3),ISNA(I3)),NA(),G3+I3) -> 0.020200538 | K3: =Z3*0.47*(44/12) -> 0.034812261 | M3: Dawadawa | N3: 70 | O3: 0.7 | P3: 0.95 | Q3: =A3&"|"&B3 -> Cashew|2 | S3: Dawadawa | T3: 0.75 | U3: 0.96 | V3: 0.995 | W3: 0.99 | Y3: =Y2*(1-AB2) + MAX(0,J2-J3) -> 0 | Z3: =J3+Y3 -> 0.020200538
A4: Cashew | B4: 3 | C4: =INDEX($N$2:$N$6, MATCH(A4, $M$2:$M$6, 0)) -> 70 | D4: =IF(B4=1,INDEX($T$2:$T$6, MATCH(A4, $S$2:$S$6, 0)),INDEX($T$2:$T$6, MATCH(A4, $S$2:$S$6, 0))*POWER(INDEX($U$2:$U$6, MATCH(A4, $S$2:$S$6, 0)),MIN(B4-1,2))*POWER(INDEX($V$2:$V$6, MATCH(A4, $S$2:$S$6, 0)),MAX(MIN(B4-3,17),0))*POWER(INDEX($W$2:$W$6, MATCH(A4, $S$2:$S$6, 0)),MAX(B4-20,0))) -> 0.676875 | E4: =C4*D4 -> 47.38125 | F4: =IFERROR(INDEX('3_GrowthInputs'!$F$2:$F$201, MATCH(Q4, '3_GrowthInputs'!$G$2:$G$201, 0)), NA()) -> 0.46164925 | G4: =IF(OR(ISNA(E4),ISNA(F4)),NA(),E4*F4/1000) -> 0.021873519 | H4: =IF(ISNA(G4),NA(),IF(G4>0,EXP(-1.085+0.9256*LN(G4))/G4,0)) -> 0.44905604 | I4: =IF(OR(ISNA(G4),ISNA(H4)),NA(),G4*H4) -> 0.0098224356 | J4: =IF(OR(ISNA(G4),ISNA(I4)),NA(),G4+I4) -> 0.031695954 | K4: =Z4*0.47*(44/12) -> 0.054622694 | M4: Mango | N4: 79 | O4: 0.7 | P4: 0.95 | Q4: =A4&"|"&B4 -> Cashew|3 | S4: Mango | T4: 0.75 | U4: 0.95 | V4: 0.99 | W4: 0.985 | Y4: =Y3*(1-AB2) + MAX(0,J3-J4) -> 0 | Z4: =J4+Y4 -> 0.031695954
A5: Cashew | B5: 4 | C5: =INDEX($N$2:$N$6, MATCH(A5, $M$2:$M$6, 0)) -> 70 | D5: =IF(B5=1,INDEX($T$2:$T$6, MATCH(A5, $S$2:$S$6, 0)),INDEX($T$2:$T$6, MATCH(A5, $S$2:$S$6, 0))*POWER(INDEX($U$2:$U$6, MATCH(A5, $S$2:$S$6, 0)),MIN(B5-1,2))*POWER(INDEX($V$2:$V$6, MATCH(A5, $S$2:$S$6, 0)),MAX(MIN(B5-3,17),0))*POWER(INDEX($W$2:$W$6, MATCH(A5, $S$2:$S$6, 0)),MAX(B5-20,0))) -> 0.67010625 | E5: =C5*D5 -> 46.907438 | F5: =IFERROR(INDEX('3_GrowthInputs'!$F$2:$F$201, MATCH(Q5, '3_GrowthInputs'!$G$2:$G$201, 0)), NA()) -> 0.76173589 | G5: =IF(OR(ISNA(E5),ISNA(F5)),NA(),E5*F5/1000) -> 0.035731079 | H5: =IF(ISNA(G5),NA(),IF(G5>0,EXP(-1.085+0.9256*LN(G5))/G5,0)) -> 0.43295609 | I5: =IF(OR(ISNA(G5),ISNA(H5)),NA(),G5*H5) -> 0.015469988 | J5: =IF(OR(ISNA(G5),ISNA(I5)),NA(),G5+I5) -> 0.051201067 | K5: =Z5*0.47*(44/12) -> 0.088236505 | M5: Moringa | N5: 79 | O5: 0.65 | P5: 0.95 | Q5: =A5&"|"&B5 -> Cashew|4 | S5: Moringa | T5: 0.7 | U5: 0.94 | V5: 0.985 | W5: 0.97 | Y5: =Y4*(1-AB2) + MAX(0,J4-J5) -> 0 | Z5: =J5+Y5 -> 0.051201067
A6: Cashew | B6: 5 | C6: =INDEX($N$2:$N$6, MATCH(A6, $M$2:$M$6, 0)) -> 70 | D6: =IF(B6=1,INDEX($T$2:$T$6, MATCH(A6, $S$2:$S$6, 0)),INDEX($T$2:$T$6, MATCH(A6, $S$2:$S$6, 0))*POWER(INDEX($U$2:$U$6, MATCH(A6, $S$2:$S$6, 0)),MIN(B6-1,2))*POWER(INDEX($V$2:$V$6, MATCH(A6, $S$2:$S$6, 0)),MAX(MIN(B6-3,17),0))*POWER(INDEX($W$2:$W$6, MATCH(A6, $S$2:$S$6, 0)),MAX(B6-20,0))) -> 0.66340519 | E6: =C6*D6 -> 46.438363 | F6: =IFERROR(INDEX('3_GrowthInputs'!$F$2:$F$201, MATCH(Q6, '3_GrowthInputs'!$G$2:$G$201, 0)), NA()) -> 1.2414554 | G6: =IF(OR(ISNA(E6),ISNA(F6)),NA(),E6*F6/1000) -> 0.057651156 | H6: =IF(ISNA(G6),NA(),IF(G6>0,EXP(-1.085+0.9256*LN(G6))/G6,0)) -> 0.41781725 | I6: =IF(OR(ISNA(G6),ISNA(H6)),NA(),G6*H6) -> 0.024087648 | J6: =IF(OR(ISNA(G6),ISNA(I6)),NA(),G6+I6) -> 0.081738804 | K6: =Z6*0.47*(44/12) -> 0.1408632 | M6: Shea | N6: 79 | O6: 0.7 | P6: 0.95 | Q6: =A6&"|"&B6 -> Cashew|5 | S6: Shea | T6: 0.75 | U6: 0.96 | V6: 0.995 | W6: 0.99 | Y6: =Y5*(1-AB2) + MAX(0,J5-J6) -> 0 | Z6: =J6+Y6 -> 0.081738804
A7: Cashew | B7: 6 | C7: =INDEX($N$2:$N$6, MATCH(A7, $M$2:$M$6, 0)) -> 70 | D7: =IF(B7=1,INDEX($T$2:$T$6, MATCH(A7, $S$2:$S$6, 0)),INDEX($T$2:$T$6, MATCH(A7, $S$2:$S$6, 0))*POWER(INDEX($U$2:$U$6, MATCH(A7, $S$2:$S$6, 0)),MIN(B7-1,2))*POWER(INDEX($V$2:$V$6, MATCH(A7, $S$2:$S$6, 0)),MAX(MIN(B7-3,17),0))*POWER(INDEX($W$2:$W$6, MATCH(A7, $S$2:$S$6, 0)),MAX(B7-20,0))) -> 0.65677114 | E7: =C7*D7 -> 45.973979 | F7: =IFERROR(INDEX('3_GrowthInputs'!$F$2:$F$201, MATCH(Q7, '3_GrowthInputs'!$G$2:$G$201, 0)), NA()) -> 1.993239 | G7: =IF(OR(ISNA(E7),ISNA(F7)),NA(),E7*F7/1000) -> 0.091637128 | H7: =IF(ISNA(G7),NA(),IF(G7>0,EXP(-1.085+0.9256*LN(G7))/G7,0)) -> 0.40365689 | I7: =IF(OR(ISNA(G7),ISNA(H7)),NA(),G7*H7) -> 0.036989958 | J7: =IF(OR(ISNA(G7),ISNA(I7)),NA(),G7+I7) -> 0.12862709 | K7: =Z7*0.47*(44/12) -> 0.22166735 | Q7: =A7&"|"&B7 -> Cashew|6 | Y7: =Y6*(1-AB2) + MAX(0,J6-J7) -> 0 | Z7: =J7+Y7 -> 0.12862709
A8: Cashew | B8: 7 | C8: =INDEX($N$2:$N$6, MATCH(A8, $M$2:$M$6, 0)) -> 70 | D8: =IF(B8=1,INDEX($T$2:$T$6, MATCH(A8, $S$2:$S$6, 0)),INDEX($T$2:$T$6, MATCH(A8, $S$2:$S$6, 0))*POWER(INDEX($U$2:$U$6, MATCH(A8, $S$2:$S$6, 0)),MIN(B8-1,2))*POWER(INDEX($V$2:$V$6, MATCH(A8, $S$2:$S$6, 0)),MAX(MIN(B8-3,17),0))*POWER(INDEX($W$2:$W$6, MATCH(A8, $S$2:$S$6, 0)),MAX(B8-20,0))) -> 0.65020342 | E8: =C8*D8 -> 45.51424 | F8: =IFERROR(INDEX('3_GrowthInputs'!$F$2:$F$201, MATCH(Q8, '3_GrowthInputs'!$G$2:$G$201, 0)), NA()) -> 3.1450812 | G8: =IF(OR(ISNA(E8),ISNA(F8)),NA(),E8*F8/1000) -> 0.14314598 | H8: =IF(ISNA(G8),NA(),IF(G8>0,EXP(-1.085+0.9256*LN(G8))/G8,0)) -> 0.39048155 | I8: =IF(OR(ISNA(G8),ISNA(H8)),NA(),G8*H8) -> 0.055895865 | J8: =IF(OR(ISNA(G8),ISNA(I8)),NA(),G8+I8) -> 0.19904185 | K8: =Z8*0.47*(44/12) -> 0.34301545 | Q8: =A8&"|"&B8 -> Cashew|7 | Y8: =Y7*(1-AB2) + MAX(0,J7-J8) -> 0 | Z8: =J8+Y8 -> 0.19904185
A9: Cashew | B9: 8 | C9: =INDEX($N$2:$N$6, MATCH(A9, $M$2:$M$6, 0)) -> 70 | D9: =IF(B9=1,INDEX($T$2:$T$6, MATCH(A9, $S$2:$S$6, 0)),INDEX($T$2:$T$6, MATCH(A9, $S$2:$S$6, 0))*POWER(INDEX($U$2:$U$6, MATCH(A9, $S$2:$S$6, 0)),MIN(B9-1,2))*POWER(INDEX($V$2:$V$6, MATCH(A9, $S$2:$S$6, 0)),MAX(MIN(B9-3,17),0))*POWER(INDEX($W$2:$W$6, MATCH(A9, $S$2:$S$6, 0)),MAX(B9-20,0))) -> 0.64370139 | E9: =C9*D9 -> 45.059097 | F9: =IFERROR(INDEX('3_GrowthInputs'!$F$2:$F$201, MATCH(Q9, '3_GrowthInputs'!$G$2:$G$201, 0)), NA()) -> 4.8692387 | G9: =IF(OR(ISNA(E9),ISNA(F9)),NA(),E9*F9/1000) -> 0.2194035 | H9: =IF(ISNA(G9),NA(),IF(G9>0,EXP(-1.085+0.9256*LN(G9))/G9,0)) -> 0.37827006 | I9: =IF(OR(ISNA(G9),ISNA(H9)),NA(),G9*H9) -> 0.082993774 | J9: =IF(OR(ISNA(G9),ISNA(I9)),NA(),G9+I9) -> 0.30239727 | K9: =Z9*0.47*(44/12) -> 0.5211313 | Q9: =A9&"|"&B9 -> Cashew|8 | Y9: =Y8*(1-AB2) + MAX(0,J8-J9) -> 0 | Z9: =J9+Y9 -> 0.30239727
A10: Cashew | B10: 9 | C10: =INDEX($N$2:$N$6, MATCH(A10, $M$2:$M$6, 0)) -> 70 | D10: =IF(B10=1,INDEX($T$2:$T$6, MATCH(A10, $S$2:$S$6, 0)),INDEX($T$2:$T$6, MATCH(A10, $S$2:$S$6, 0))*POWER(INDEX($U$2:$U$6, MATCH(A10, $S$2:$S$6, 0)),MIN(B10-1,2))*POWER(INDEX($V$2:$V$6, MATCH(A10, $S$2:$S$6, 0)),MAX(MIN(B10-3,17),0))*POWER(INDEX($W$2:$W$6, MATCH(A10, $S$2:$S$6, 0)),MAX(B10-20,0))) -> 0.63726438 | E10: =C10*D10 -> 44.608506 | F10: =IFERROR(INDEX('3_GrowthInputs'!$F$2:$F$201, MATCH(Q10, '3_GrowthInputs'!$G$2:$G$201, 0)), NA()) -> 7.3779824 | G10: =IF(OR(ISNA(E10),ISNA(F10)),NA(),E10*F10/1000) -> 0.32912077 | H10: =IF(ISNA(G10),NA(),IF(G10>0,EXP(-1.085+0.9256*LN(G10))/G10,0)) -> 0.36702805 | I10: =IF(OR(ISNA(G10),ISNA(H10)),NA(),G10*H10) -> 0.12079655 | J10: =IF(OR(ISNA(G10),ISNA(I10)),NA(),G10+I10) -> 0.44991733 | K10: =Z10*0.47*(44/12) -> 0.77535753 | Q10: =A10&"|"&B10 -> Cashew|9 | Y10: =Y9*(1-AB2) + MAX(0,J9-J10) -> 0 | Z10: =J10+Y10 -> 0.44991733
A11: Cashew | B11: 10 | C11: =INDEX($N$2:$N$6, MATCH(A11, $M$2:$M$6, 0)) -> 70 | D11: =IF(B11=1,INDEX($T$2:$T$6, MATCH(A11, $S$2:$S$6, 0)),INDEX($T$2:$T$6, MATCH(A11, $S$2:$S$6, 0))*POWER(INDEX($U$2:$U$6, MATCH(A11, $S$2:$S$6, 0)),MIN(B11-1,2))*POWER(INDEX($V$2:$V$6, MATCH(A11, $S$2:$S$6, 0)),MAX(MIN(B11-3,17),0))*POWER(INDEX($W$2:$W$6, MATCH(A11, $S$2:$S$6, 0)),MAX(B11-20,0))) -> 0.63089173 | E11: =C11*D11 -> 44.162421 | F11: =IFERROR(INDEX('3_GrowthInputs'!$F$2:$F$201, MATCH(Q11, '3_GrowthInputs'!$G$2:$G$201, 0)), NA()) -> 10.918284 | G11: =IF(OR(ISNA(E11),ISNA(F11)),NA(),E11*F11/1000) -> 0.48217788 | H11: =IF(ISNA(G11),NA(),IF(G11>0,EXP(-1.085+0.9256*LN(G11))/G11,0)) -> 0.35674662 | I11: =IF(OR(ISNA(G11),ISNA(H11)),NA(),G11*H11) -> 0.17201533 | J11: =IF(OR(ISNA(G11),ISNA(I11)),NA(),G11+I11) -> 0.65419321 | K11: =Z11*0.47*(44/12) -> 1.127393 | Q11: =A11&"|"&B11 -> Cashew|10 | Y11: =Y10*(1-AB2) + MAX(0,J10-J11) -> 0 | Z11: =J11+Y11 -> 0.65419321
A12: Cashew | B12: 11 | C12: =INDEX($N$2:$N$6, MATCH(A12, $M$2:$M$6, 0)) -> 70 | D12: =IF(B12=1,INDEX($T$2:$T$6, MATCH(A12, $S$2:$S$6, 0)),INDEX($T$2:$T$6, MATCH(A12, $S$2:$S$6, 0))*POWER(INDEX($U$2:$U$6, MATCH(A12, $S$2:$S$6, 0)),MIN(B12-1,2))*POWER(INDEX($V$2:$V$6, MATCH(A12, $S$2:$S$6, 0)),MAX(MIN(B12-3,17),0))*POWER(INDEX($W$2:$W$6, MATCH(A12, $S$2:$S$6, 0)),MAX(B12-20,0))) -> 0.62458282 | E12: =C12*D12 -> 43.720797 | F12: =IFERROR(INDEX('3_GrowthInputs'!$F$2:$F$201, MATCH(Q12, '3_GrowthInputs'!$G$2:$G$201, 0)), NA()) -> 15.748319 | G12: =IF(OR(ISNA(E12),ISNA(F12)),NA(),E12*F12/1000) -> 0.68852907 | H12: =IF(ISNA(G12),NA(),IF(G12>0,EXP(-1.085+0.9256*LN(G12))/G12,0)) -> 0.3474154 | I12: =IF(OR(ISNA(G12),ISNA(H12)),NA(),G12*H12) -> 0.2392056 | J12: =IF(OR(ISNA(G12),ISNA(I12)),NA(),G12+I12) -> 0.92773467 | K12: =Z12*0.47*(44/12) -> 1.5987961 | Q12: =A12&"|"&B12 -> Cashew|11 | Y12: =Y11*(1-AB2) + MAX(0,J11-J12) -> 0 | Z12: =J12+Y12 -> 0.92773467
A13: Cashew | B13: 12 | C13: =INDEX($N$2:$N$6, MATCH(A13, $M$2:$M$6, 0)) -> 70 | D13: =IF(B13=1,INDEX($T$2:$T$6, MATCH(A13, $S$2:$S$6, 0)),INDEX($T$2:$T$6, MATCH(A13, $S$2:$S$6, 0))*POWER(INDEX($U$2:$U$6, MATCH(A13, $S$2:$S$6, 0)),MIN(B13-1,2))*POWER(INDEX($V$2:$V$6, MATCH(A13, $S$2:$S$6, 0)),MAX(MIN(B13-3,17),0))*POWER(INDEX($W$2:$W$6, MATCH(A13, $S$2:$S$6, 0)),MAX(B13-20,0))) -> 0.61833699 | E13: =C13*D13 -> 43.283589 | F13: =IFERROR(INDEX('3_GrowthInputs'!$F$2:$F$201, MATCH(Q13, '3_GrowthInputs'!$G$2:$G$201, 0)), NA()) -> 22.108795 | G13: =IF(OR(ISNA(E13),ISNA(F13)),NA(),E13*F13/1000) -> 0.95694799 | H13: =IF(ISNA(G13),NA(),IF(G13>0,EXP(-1.085+0.9256*LN(G13))/G13,0)) -> 0.33900991 | I13: =IF(OR(ISNA(G13),ISNA(H13)),NA(),G13*H13) -> 0.32441485 | J13: =IF(OR(ISNA(G13),ISNA(I13)),NA(),G13+I13) -> 1.2813628 | K13: =Z13*0.47*(44/12) -> 2.2082153 | Q13: =A13&"|"&B13 -> Cashew|12 | Y13: =Y12*(1-AB2) + MAX(0,J12-J13) -> 0 | Z13: =J13+Y13 -> 1.2813628
A14: Cashew | B14: 13 | C14: =INDEX($N$2:$N$6, MATCH(A14, $M$2:$M$6, 0)) -> 70 | D14: =IF(B14=1,INDEX($T$2:$T$6, MATCH(A14, $S$2:$S$6, 0)),INDEX($T$2:$T$6, MATCH(A14, $S$2:$S$6, 0))*POWER(INDEX($U$2:$U$6, MATCH(A14, $S$2:$S$6, 0)),MIN(B14-1,2))*POWER(INDEX($V$2:$V$6, MATCH(A14, $S$2:$S$6, 0)),MAX(MIN(B14-3,17),0))*POWER(INDEX($W$2:$W$6, MATCH(A14, $S$2:$S$6, 0)),MAX(B14-20,0))) -> 0.61215362 | E14: =C14*D14 -> 42.850753 | F14: =IFERROR(INDEX('3_GrowthInputs'!$F$2:$F$201, MATCH(Q14, '3_GrowthInputs'!$G$2:$G$201, 0)), NA()) -> 30.183455 | G14: =IF(OR(ISNA(E14),ISNA(F14)),NA(),E14*F14/1000) -> 1.2933838 | H14: =IF(ISNA(G14),NA(),IF(G14>0,EXP(-1.085+0.9256*LN(G14))/G14,0)) -> 0.33149575 | I14: =IF(OR(ISNA(G14),ISNA(H14)),NA(),G14*H14) -> 0.42875123 | J14: =IF(OR(ISNA(G14),ISNA(I14)),NA(),G14+I14) -> 1.722135 | K14: =Z14*0.47*(44/12) -> 2.9678126 | Q14: =A14&"|"&B14 -> Cashew|13 | Y14: =Y13*(1-AB2) + MAX(0,J13-J14) -> 0 | Z14: =J14+Y14 -> 1.722135
A15: Cashew | B15: 14 | C15: =INDEX($N$2:$N$6, MATCH(A15, $M$2:$M$6, 0)) -> 70 | D15: =IF(B15=1,INDEX($T$2:$T$6, MATCH(A15, $S$2:$S$6, 0)),INDEX($T$2:$T$6, MATCH(A15, $S$2:$S$6, 0))*POWER(INDEX($U$2:$U$6, MATCH(A15, $S$2:$S$6, 0)),MIN(B15-1,2))*POWER(INDEX($V$2:$V$6, MATCH(A15, $S$2:$S$6, 0)),MAX(MIN(B15-3,17),0))*POWER(INDEX($W$2:$W$6, MATCH(A15, $S$2:$S$6, 0)),MAX(B15-20,0))) -> 0.60603208 | E15: =C15*D15 -> 42.422246 | F15: =IFERROR(INDEX('3_GrowthInputs'!$F$2:$F$201, MATCH(Q15, '3_GrowthInputs'!$G$2:$G$201, 0)), NA()) -> 40.054008 | G15: =IF(OR(ISNA(E15),ISNA(F15)),NA(),E15*F15/1000) -> 1.699181 | H15: =IF(ISNA(G15),NA(),IF(G15>0,EXP(-1.085+0.9256*LN(G15))/G15,0)) -> 0.32483339 | I15: =IF(OR(ISNA(G15),ISNA(H15)),NA(),G15*H15) -> 0.55195071 | J15: =IF(OR(ISNA(G15),ISNA(I15)),NA(),G15+I15) -> 2.2511317 | K15: =Z15*0.47*(44/12) -> 3.8794503 | Q15: =A15&"|"&B15 -> Cashew|14 | Y15: =Y14*(1-AB2) + MAX(0,J14-J15) -> 0 | Z15: =J15+Y15 -> 2.2511317
A16: Cashew | B16: 15 | C16: =INDEX($N$2:$N$6, MATCH(A16, $M$2:$M$6, 0)) -> 70 | D16: =IF(B16=1,INDEX($T$2:$T$6, MATCH(A16, $S$2:$S$6, 0)),INDEX($T$2:$T$6, MATCH(A16, $S$2:$S$6, 0))*POWER(INDEX($U$2:$U$6, MATCH(A16, $S$2:$S$6, 0)),MIN(B16-1,2))*POWER(INDEX($V$2:$V$6, MATCH(A16, $S$2:$S$6, 0)),MAX(MIN(B16-3,17),0))*POWER(INDEX($W$2:$W$6, MATCH(A16, $S$2:$S$6, 0)),MAX(B16-20,0))) -> 0.59997176 | E16: =C16*D16 -> 41.998023 | F16: =IFERROR(INDEX('3_GrowthInputs'!$F$2:$F$201, MATCH(Q16, '3_GrowthInputs'!$G$2:$G$201, 0)), NA()) -> 51.663063 | G16: =IF(OR(ISNA(E16),ISNA(F16)),NA(),E16*F16/1000) -> 2.1697465 | H16: =IF(ISNA(G16),NA(),IF(G16>0,EXP(-1.085+0.9256*LN(G16))/G16,0)) -> 0.31897868 | I16: =IF(OR(ISNA(G16),ISNA(H16)),NA(),G16*H16) -> 0.69210288 | J16: =IF(OR(ISNA(G16),ISNA(I16)),NA(),G16+I16) -> 2.8618494 | K16: =Z16*0.47*(44/12) -> 4.9319205 | Q16: =A16&"|"&B16 -> Cashew|15 | Y16: =Y15*(1-AB2) + MAX(0,J15-J16) -> 0 | Z16: =J16+Y16 -> 2.8618494
A17: Cashew | B17: 16 | C17: =INDEX($N$2:$N$6, MATCH(A17, $M$2:$M$6, 0)) -> 70 | D17: =IF(B17=1,INDEX($T$2:$T$6, MATCH(A17, $S$2:$S$6, 0)),INDEX($T$2:$T$6, MATCH(A17, $S$2:$S$6, 0))*POWER(INDEX($U$2:$U$6, MATCH(A17, $S$2:$S$6, 0)),MIN(B17-1,2))*POWER(INDEX($V$2:$V$6, MATCH(A17, $S$2:$S$6, 0)),MAX(MIN(B17-3,17),0))*POWER(INDEX($W$2:$W$6, MATCH(A17, $S$2:$S$6, 0)),MAX(B17-20,0))) -> 0.59397204 | E17: =C17*D17 -> 41.578043 | F17: =IFERROR(INDEX('3_GrowthInputs'!$F$2:$F$201, MATCH(Q17, '3_GrowthInputs'!$G$2:$G$201, 0)), NA()) -> 64.817597 | G17: =IF(OR(ISNA(E17),ISNA(F17)),NA(),E17*F17/1000) -> 2.6949888 | H17: =IF(ISNA(G17),NA(),IF(G17>0,EXP(-1.085+0.9256*LN(G17))/G17,0)) -> 0.31387523 | I17: =IF(OR(ISNA(G17),ISNA(H17)),NA(),G17*H17) -> 0.84589025 | J17: =IF(OR(ISNA(G17),ISNA(I17)),NA(),G17+I17) -> 3.5408791 | K17: =Z17*0.47*(44/12) -> 6.102115 | Q17: =A17&"|"&B17 -> Cashew|16 | Y17: =Y16*(1-AB2) + MAX(0,J16-J17) -> 0 | Z17: =J17+Y17 -> 3.5408791
A18: Cashew | B18: 17 | C18: =INDEX($N$2:$N$6, MATCH(A18, $M$2:$M$6, 0)) -> 70 | D18: =IF(B18=1,INDEX($T$2:$T$6, MATCH(A18, $S$2:$S$6, 0)),INDEX($T$2:$T$6, MATCH(A18, $S$2:$S$6, 0))*POWER(INDEX($U$2:$U$6, MATCH(A18, $S$2:$S$6, 0)),MIN(B18-1,2))*POWER(INDEX($V$2:$V$6, MATCH(A18, $S$2:$S$6, 0)),MAX(MIN(B18-3,17),0))*POWER(INDEX($W$2:$W$6, MATCH(A18, $S$2:$S$6, 0)),MAX(B18-20,0))) -> 0.58803232 | E18: =C18*D18 -> 41.162263 | F18: =IFERROR(INDEX('3_GrowthInputs'!$F$2:$F$201, MATCH(Q18, '3_GrowthInputs'!$G$2:$G$201, 0)), NA()) -> 79.188627 | G18: =IF(OR(ISNA(E18),ISNA(F18)),NA(),E18*F18/1000) -> 3.259583 | H18: =IF(ISNA(G18),NA(),IF(G18>0,EXP(-1.085+0.9256*LN(G18))/G18,0)) -> 0.30946478 | I18: =IF(OR(ISNA(G18),ISNA(H18)),NA(),G18*H18) -> 1.0087262 | J18: =IF(OR(ISNA(G18),ISNA(I18)),NA(),G18+I18) -> 4.2683092 | K18: =Z18*0.47*(44/12) -> 7.3557195 | Q18: =A18&"|"&B18 -> Cashew|17 | Y18: =Y17*(1-AB2) + MAX(0,J17-J18) -> 0 | Z18: =J18+Y18 -> 4.2683092
A19: Cashew | B19: 18 | C19: =INDEX($N$2:$N$6, MATCH(A19, $M$2:$M$6, 0)) -> 70 | D19: =IF(B19=1,INDEX($T$2:$T$6, MATCH(A19, $S$2:$S$6, 0)),INDEX($T$2:$T$6, MATCH(A19, $S$2:$S$6, 0))*POWER(INDEX($U$2:$U$6, MATCH(A19, $S$2:$S$6, 0)),MIN(B19-1,2))*POWER(INDEX($V$2:$V$6, MATCH(A19, $S$2:$S$6, 0)),MAX(MIN(B19-3,17),0))*POWER(INDEX($W$2:$W$6, MATCH(A19, $S$2:$S$6, 0)),MAX(B19-20,0))) -> 0.582152 | E19: =C19*D19 -> 40.75064 | F19: =IFERROR(INDEX('3_GrowthInputs'!$F$2:$F$201, MATCH(Q19, '3_GrowthInputs'!$G$2:$G$201, 0)), NA()) -> 94.378166 | G19: =IF(OR(ISNA(E19),ISNA(F19)),NA(),E19*F19/1000) -> 3.8459706 | H19: =IF(ISNA(G19),NA(),IF(G19>0,EXP(-1.085+0.9256*LN(G19))/G19,0)) -> 0.30567931 | I19: =IF(OR(ISNA(G19),ISNA(H19)),NA(),G19*H19) -> 1.1756336 | J19: =IF(OR(ISNA(G19),ISNA(I19)),NA(),G19+I19) -> 5.0216043 | K19: =Z19*0.47*(44/12) -> 8.6538981 | Q19: =A19&"|"&B19 -> Cashew|18 | Y19: =Y18*(1-AB2) + MAX(0,J18-J19) -> 0 | Z19: =J19+Y19 -> 5.0216043
A20: Cashew | B20: 19 | C20: =INDEX($N$2:$N$6, MATCH(A20, $M$2:$M$6, 0)) -> 70 | D20: =IF(B20=1,INDEX($T$2:$T$6, MATCH(A20, $S$2:$S$6, 0)),INDEX($T$2:$T$6, MATCH(A20, $S$2:$S$6, 0))*POWER(INDEX($U$2:$U$6, MATCH(A20, $S$2:$S$6, 0)),MIN(B20-1,2))*POWER(INDEX($V$2:$V$6, MATCH(A20, $S$2:$S$6, 0)),MAX(MIN(B20-3,17),0))*POWER(INDEX($W$2:$W$6, MATCH(A20, $S$2:$S$6, 0)),MAX(B20-20,0))) -> 0.57633048 | E20: =C20*D20 -> 40.343134 | F20: =IFERROR(INDEX('3_GrowthInputs'!$F$2:$F$201, MATCH(Q20, '3_GrowthInputs'!$G$2:$G$201, 0)), NA()) -> 109.90193 | G20: =IF(OR(ISNA(E20),ISNA(F20)),NA(),E20*F20/1000) -> 4.4337883 | H20: =IF(ISNA(G20),NA(),IF(G20>0,EXP(-1.085+0.9256*LN(G20))/G20,0)) -> 0.30246173 | I20: =IF(OR(ISNA(G20),ISNA(H20)),NA(),G20*H20) -> 1.3410513 | J20: =IF(OR(ISNA(G20),ISNA(I20)),NA(),G20+I20) -> 5.7748395 | K20: =Z20*0.47*(44/12) -> 9.9519735 | Q20: =A20&"|"&B20 -> Cashew|19 | Y20: =Y19*(1-AB2) + MAX(0,J19-J20) -> 0 | Z20: =J20+Y20 -> 5.7748395
A21: Cashew | B21: 20 | C21: =INDEX($N$2:$N$6, MATCH(A21, $M$2:$M$6, 0)) -> 70 | D21: =IF(B21=1,INDEX($T$2:$T$6, MATCH(A21, $S$2:$S$6, 0)),INDEX($T$2:$T$6, MATCH(A21, $S$2:$S$6, 0))*POWER(INDEX($U$2:$U$6, MATCH(A21, $S$2:$S$6, 0)),MIN(B21-1,2))*POWER(INDEX($V$2:$V$6, MATCH(A21, $S$2:$S$6, 0)),MAX(MIN(B21-3,17),0))*POWER(INDEX($W$2:$W$6, MATCH(A21, $S$2:$S$6, 0)),MAX(B21-20,0))) -> 0.57056717 | E21: =C21*D21 -> 39.939702 | F21: =IFERROR(INDEX('3_GrowthInputs'!$F$2:$F$201, MATCH(Q21, '3_GrowthInputs'!$G$2:$G$201, 0)), NA()) -> 125.31585 | G21: =IF(OR(ISNA(E21),ISNA(F21)),NA(),E21*F21/1000) -> 5.0050778 | H21: =IF(ISNA(G21),NA(),IF(G21>0,EXP(-1.085+0.9256*LN(G21))/G21,0)) -> 0.29974664 | I21: =IF(OR(ISNA(G21),ISNA(H21)),NA(),G21*H21) -> 1.5002553 | J21: =IF(OR(ISNA(G21),ISNA(I21)),NA(),G21+I21) -> 6.5053331 | K21: =Z21*0.47*(44/12) -> 11.210857 | Q21: =A21&"|"&B21 -> Cashew|20 | Y21: =Y20*(1-AB2) + MAX(0,J20-J21) -> 0 | Z21: =J21+Y21 -> 6.5053331
A22: Cashew | B22: 21 | C22: =INDEX($N$2:$N$6, MATCH(A22, $M$2:$M$6, 0)) -> 70 | D22: =IF(B22=1,INDEX($T$2:$T$6, MATCH(A22, $S$2:$S$6, 0)),INDEX($T$2:$T$6, MATCH(A22, $S$2:$S$6, 0))*POWER(INDEX($U$2:$U$6, MATCH(A22, $S$2:$S$6, 0)),MIN(B22-1,2))*POWER(INDEX($V$2:$V$6, MATCH(A22, $S$2:$S$6, 0)),MAX(MIN(B22-3,17),0))*POWER(INDEX($W$2:$W$6, MATCH(A22, $S$2:$S$6, 0)),MAX(B22-20,0))) -> 0.56200867 | E22: =C22*D22 -> 39.340607 | F22: =IFERROR(INDEX('3_GrowthInputs'!$F$2:$F$201, MATCH(Q22, '3_GrowthInputs'!$G$2:$G$201, 0)), NA()) -> 140.233 | G22: =IF(OR(ISNA(E22),ISNA(F22)),NA(),E22*F22/1000) -> 5.5168515 | H22: =IF(ISNA(G22),NA(),IF(G22>0,EXP(-1.085+0.9256*LN(G22))/G22,0)) -> 0.29758337 | I22: =IF(OR(ISNA(G22),ISNA(H22)),NA(),G22*H22) -> 1.6417232 | J22: =IF(OR(ISNA(G22),ISNA(I22)),NA(),G22+I22) -> 7.1585747 | K22: =Z22*0.47*(44/12) -> 12.33661 | Q22: =A22&"|"&B22 -> Cashew|21 | Y22: =Y21*(1-AB2) + MAX(0,J21-J22) -> 0 | Z22: =J22+Y22 -> 7.1585747
A23: Cashew | B23: 22 | C23: =INDEX($N$2:$N$6, MATCH(A23, $M$2:$M$6, 0)) -> 70 | D23: =IF(B23=1,INDEX($T$2:$T$6, MATCH(A23, $S$2:$S$6, 0)),INDEX($T$2:$T$6, MATCH(A23, $S$2:$S$6, 0))*POWER(INDEX($U$2:$U$6, MATCH(A23, $S$2:$S$6, 0)),MIN(B23-1,2))*POWER(INDEX($V$2:$V$6, MATCH(A23, $S$2:$S$6, 0)),MAX(MIN(B23-3,17),0))*POWER(INDEX($W$2:$W$6, MATCH(A23, $S$2:$S$6, 0)),MAX(B23-20,0))) -> 0.55357854 | E23: =C23*D23 -> 38.750498 | F23: =IFERROR(INDEX('3_GrowthInputs'!$F$2:$F$201, MATCH(Q23, '3_GrowthInputs'!$G$2:$G$201, 0)), NA()) -> 154.31623 | G23: =IF(OR(ISNA(E23),ISNA(F23)),NA(),E23*F23/1000) -> 5.9798307 | H23: =IF(ISNA(G23),NA(),IF(G23>0,EXP(-1.085+0.9256*LN(G23))/G23,0)) -> 0.29580454 | I23: =IF(OR(ISNA(G23),ISNA(H23)),NA(),G23*H23) -> 1.7688611 | J23: =IF(OR(ISNA(G23),ISNA(I23)),NA(),G23+I23) -> 7.7486917 | K23: =Z23*0.47*(44/12) -> 13.353579 | Q23: =A23&"|"&B23 -> Cashew|22 | Y23: =Y22*(1-AB2) + MAX(0,J22-J23) -> 0 | Z23: =J23+Y23 -> 7.7486917
A24: Cashew | B24: 23 | C24: =INDEX($N$2:$N$6, MATCH(A24, $M$2:$M$6, 0)) -> 70 | D24: =IF(B24=1,INDEX($T$2:$T$6, MATCH(A24, $S$2:$S$6, 0)),INDEX($T$2:$T$6, MATCH(A24, $S$2:$S$6, 0))*POWER(INDEX($U$2:$U$6, MATCH(A24, $S$2:$S$6, 0)),MIN(B24-1,2))*POWER(INDEX($V$2:$V$6, MATCH(A24, $S$2:$S$6, 0)),MAX(MIN(B24-3,17),0))*POWER(INDEX($W$2:$W$6, MATCH(A24, $S$2:$S$6, 0)),MAX(B24-20,0))) -> 0.54527486 | E24: =C24*D24 -> 38.16924 | F24: =IFERROR(INDEX('3_GrowthInputs'!$F$2:$F$201, MATCH(Q24, '3_GrowthInputs'!$G$2:$G$201, 0)), NA()) -> 167.34989 | G24: =IF(OR(ISNA(E24),ISNA(F24)),NA(),E24*F24/1000) -> 6.3876182 | H24: =IF(ISNA(G24),NA(),IF(G24>0,EXP(-1.085+0.9256*LN(G24))/G24,0)) -> 0.29435626 | I24: =IF(OR(ISNA(G24),ISNA(H24)),NA(),G24*H24) -> 1.8802354 | J24: =IF(OR(ISNA(G24),ISNA(I24)),NA(),G24+I24) -> 8.2678536 | K24: =Z24*0.47*(44/12) -> 14.248268 | Q24: =A24&"|"&B24 -> Cashew|23 | Y24: =Y23*(1-AB2) + MAX(0,J23-J24) -> 0 | Z24: =J24+Y24 -> 8.2678536
A25: Cashew | B25: 24 | C25: =INDEX($N$2:$N$6, MATCH(A25, $M$2:$M$6, 0)) -> 70 | D25: =IF(B25=1,INDEX($T$2:$T$6, MATCH(A25, $S$2:$S$6, 0)),INDEX($T$2:$T$6, MATCH(A25, $S$2:$S$6, 0))*POWER(INDEX($U$2:$U$6, MATCH(A25, $S$2:$S$6, 0)),MIN(B25-1,2))*POWER(INDEX($V$2:$V$6, MATCH(A25, $S$2:$S$6, 0)),MAX(MIN(B25-3,17),0))*POWER(INDEX($W$2:$W$6, MATCH(A25, $S$2:$S$6, 0)),MAX(B25-20,0))) -> 0.53709574 | E25: =C25*D25 -> 37.596701 | F25: =IFERROR(INDEX('3_GrowthInputs'!$F$2:$F$201, MATCH(Q25, '3_GrowthInputs'!$G$2:$G$201, 0)), NA()) -> 179.17751 | G25: =IF(OR(ISNA(E25),ISNA(F25)),NA(),E25*F25/1000) -> 6.7364833 | H25: =IF(ISNA(G25),NA(),IF(G25>0,EXP(-1.085+0.9256*LN(G25))/G25,0)) -> 0.29319398 | I25: =IF(OR(ISNA(G25),ISNA(H25)),NA(),G25*H25) -> 1.9750964 | J25: =IF(OR(ISNA(G25),ISNA(I25)),NA(),G25+I25) -> 8.7115797 | K25: =Z25*0.47*(44/12) -> 15.012956 | Q25: =A25&"|"&B25 -> Cashew|24 | Y25: =Y24*(1-AB2) + MAX(0,J24-J25) -> 0 | Z25: =J25+Y25 -> 8.7115797
A26: Cashew | B26: 25 | C26: =INDEX($N$2:$N$6, MATCH(A26, $M$2:$M$6, 0)) -> 70 | D26: =IF(B26=1,INDEX($T$2:$T$6, MATCH(A26, $S$2:$S$6, 0)),INDEX($T$2:$T$6, MATCH(A26, $S$2:$S$6, 0))*POWER(INDEX($U$2:$U$6, MATCH(A26, $S$2:$S$6, 0)),MIN(B26-1,2))*POWER(INDEX($V$2:$V$6, MATCH(A26, $S$2:$S$6, 0)),MAX(MIN(B26-3,17),0))*POWER(INDEX($W$2:$W$6, MATCH(A26, $S$2:$S$6, 0)),MAX(B26-20,0))) -> 0.5290393 | E26: =C26*D26 -> 37.032751 | F26: =IFERROR(INDEX('3_GrowthInputs'!$F$2:$F$201, MATCH(Q26, '3_GrowthInputs'!$G$2:$G$201, 0)), NA()) -> 189.74599 | G26: =IF(OR(ISNA(E26),ISNA(F26)),NA(),E26*F26/1000) -> 7.026816 | H26: =IF(ISNA(G26),NA(),IF(G26>0,EXP(-1.085+0.9256*LN(G26))/G26,0)) -> 0.29227499 | I26: =IF(OR(ISNA(G26),ISNA(H26)),NA(),G26*H26) -> 2.0537625 | J26: =IF(OR(ISNA(G26),ISNA(I26)),NA(),G26+I26) -> 9.0805785 | K26: =Z26*0.47*(44/12) -> 15.648864 | Q26: =A26&"|"&B26 -> Cashew|25 | Y26: =Y25*(1-AB2) + MAX(0,J25-J26) -> 0 | Z26: =J26+Y26 -> 9.0805785
A27: Cashew | B27: 26 | C27: =INDEX($N$2:$N$6, MATCH(A27, $M$2:$M$6, 0)) -> 70 | D27: =IF(B27=1,INDEX($T$2:$T$6, MATCH(A27, $S$2:$S$6, 0)),INDEX($T$2:$T$6, MATCH(A27, $S$2:$S$6, 0))*POWER(INDEX($U$2:$U$6, MATCH(A27, $S$2:$S$6, 0)),MIN(B27-1,2))*POWER(INDEX($V$2:$V$6, MATCH(A27, $S$2:$S$6, 0)),MAX(MIN(B27-3,17),0))*POWER(INDEX($W$2:$W$6, MATCH(A27, $S$2:$S$6, 0)),MAX(B27-20,0))) -> 0.52110371 | E27: =C27*D27 -> 36.47726 | F27: =IFERROR(INDEX('3_GrowthInputs'!$F$2:$F$201, MATCH(Q27, '3_GrowthInputs'!$G$2:$G$201, 0)), NA()) -> 199.06328 | G27: =IF(OR(ISNA(E27),ISNA(F27)),NA(),E27*F27/1000) -> 7.2612831 | H27: =IF(ISNA(G27),NA(),IF(G27>0,EXP(-1.085+0.9256*LN(G27))/G27,0)) -> 0.29156212 | I27: =IF(OR(ISNA(G27),ISNA(H27)),NA(),G27*H27) -> 2.1171151 | J27: =IF(OR(ISNA(G27),ISNA(I27)),NA(),G27+I27) -> 9.3783981 | K27: =Z27*0.47*(44/12) -> 16.162106 | Q27: =A27&"|"&B27 -> Cashew|26 | Y27: =Y26*(1-AB2) + MAX(0,J26-J27) -> 0 | Z27: =J27+Y27 -> 9.3783981
A28: Cashew | B28: 27 | C28: =INDEX($N$2:$N$6, MATCH(A28, $M$2:$M$6, 0)) -> 70 | D28: =IF(B28=1,INDEX($T$2:$T$6, MATCH(A28, $S$2:$S$6, 0)),INDEX($T$2:$T$6, MATCH(A28, $S$2:$S$6, 0))*POWER(INDEX($U$2:$U$6, MATCH(A28, $S$2:$S$6, 0)),MIN(B28-1,2))*POWER(INDEX($V$2:$V$6, MATCH(A28, $S$2:$S$6, 0)),MAX(MIN(B28-3,17),0))*POWER(INDEX($W$2:$W$6, MATCH(A28, $S$2:$S$6, 0)),MAX(B28-20,0))) -> 0.51328715 | E28: =C28*D28 -> 35.930101 | F28: =IFERROR(INDEX('3_GrowthInputs'!$F$2:$F$201, MATCH(Q28, '3_GrowthInputs'!$G$2:$G$201, 0)), NA()) -> 207.18847 | G28: =IF(OR(ISNA(E28),ISNA(F28)),NA(),E28*F28/1000) -> 7.4443028 | H28: =IF(ISNA(G28),NA(),IF(G28>0,EXP(-1.085+0.9256*LN(G28))/G28,0)) -> 0.29102264 | I28: =IF(OR(ISNA(G28),ISNA(H28)),NA(),G28*H28) -> 2.1664607 | J28: =IF(OR(ISNA(G28),ISNA(I28)),NA(),G28+I28) -> 9.6107634 | K28: =Z28*0.47*(44/12) -> 16.562549 | Q28: =A28&"|"&B28 -> Cashew|27 | Y28: =Y27*(1-AB2) + MAX(0,J27-J28) -> 0 | Z28: =J28+Y28 -> 9.6107634
A29: Cashew | B29: 28 | C29: =INDEX($N$2:$N$6, MATCH(A29, $M$2:$M$6, 0)) -> 70 | D29: =IF(B29=1,INDEX($T$2:$T$6, MATCH(A29, $S$2:$S$6, 0)),INDEX($T$2:$T$6, MATCH(A29, $S$2:$S$6, 0))*POWER(INDEX($U$2:$U$6, MATCH(A29, $S$2:$S$6, 0)),MIN(B29-1,2))*POWER(INDEX($V$2:$V$6, MATCH(A29, $S$2:$S$6, 0)),MAX(MIN(B29-3,17),0))*POWER(INDEX($W$2:$W$6, MATCH(A29, $S$2:$S$6, 0)),MAX(B29-20,0))) -> 0.50558785 | E29: =C29*D29 -> 35.391149 | F29: =IFERROR(INDEX('3_GrowthInputs'!$F$2:$F$201, MATCH(Q29, '3_GrowthInputs'!$G$2:$G$201, 0)), NA()) -> 214.19668 | G29: =IF(OR(ISNA(E29),ISNA(F29)),NA(),E29*F29/1000) -> 7.5806668 | H29: =IF(ISNA(G29),NA(),IF(G29>0,EXP(-1.085+0.9256*LN(G29))/G29,0)) -> 0.29062988 | I29: =IF(OR(ISNA(G29),ISNA(H29)),NA(),G29*H29) -> 2.2031683 | J29: =IF(OR(ISNA(G29),ISNA(I29)),NA(),G29+I29) -> 9.7838351 | K29: =Z29*0.47*(44/12) -> 16.860809 | Q29: =A29&"|"&B29 -> Cashew|28 | Y29: =Y28*(1-AB2) + MAX(0,J28-J29) -> 0 | Z29: =J29+Y29 -> 9.7838351
A30: Cashew | B30: 29 | C30: =INDEX($N$2:$N$6, MATCH(A30, $M$2:$M$6, 0)) -> 70 | D30: =IF(B30=1,INDEX($T$2:$T$6, MATCH(A30, $S$2:$S$6, 0)),INDEX($T$2:$T$6, MATCH(A30, $S$2:$S$6, 0))*POWER(INDEX($U$2:$U$6, MATCH(A30, $S$2:$S$6, 0)),MIN(B30-1,2))*POWER(INDEX($V$2:$V$6, MATCH(A30, $S$2:$S$6, 0)),MAX(MIN(B30-3,17),0))*POWER(INDEX($W$2:$W$6, MATCH(A30, $S$2:$S$6, 0)),MAX(B30-20,0))) -> 0.49800403 | E30: =C30*D30 -> 34.860282 | F30: =IFERROR(INDEX('3_GrowthInputs'!$F$2:$F$201, MATCH(Q30, '3_GrowthInputs'!$G$2:$G$201, 0)), NA()) -> 220.18949 | G30: =IF(OR(ISNA(E30),ISNA(F30)),NA(),E30*F30/1000) -> 7.6758679 | H30: =IF(ISNA(G30),NA(),IF(G30>0,EXP(-1.085+0.9256*LN(G30))/G30,0)) -> 0.29036014 | I30: =IF(OR(ISNA(G30),ISNA(H30)),NA(),G30*H30) -> 2.2287661 | J30: =IF(OR(ISNA(G30),ISNA(I30)),NA(),G30+I30) -> 9.904634 | K30: =Z30*0.47*(44/12) -> 17.068986 | Q30: =A30&"|"&B30 -> Cashew|29 | Y30: =Y29*(1-AB2) + MAX(0,J29-J30) -> 0 | Z30: =J30+Y30 -> 9.904634
A31: Cashew | B31: 30 | C31: =INDEX($N$2:$N$6, MATCH(A31, $M$2:$M$6, 0)) -> 70 | D31: =IF(B31=1,INDEX($T$2:$T$6, MATCH(A31, $S$2:$S$6, 0)),INDEX($T$2:$T$6, MATCH(A31, $S$2:$S$6, 0))*POWER(INDEX($U$2:$U$6, MATCH(A31, $S$2:$S$6, 0)),MIN(B31-1,2))*POWER(INDEX($V$2:$V$6, MATCH(A31, $S$2:$S$6, 0)),MAX(MIN(B31-3,17),0))*POWER(INDEX($W$2:$W$6, MATCH(A31, $S$2:$S$6, 0)),MAX(B31-20,0))) -> 0.49053397 | E31: =C31*D31 -> 34.337378 | F31: =IFERROR(INDEX('3_GrowthInputs'!$F$2:$F$201, MATCH(Q31, '3_GrowthInputs'!$G$2:$G$201, 0)), NA()) -> 225.27825 | G31: =IF(OR(ISNA(E31),ISNA(F31)),NA(),E31*F31/1000) -> 7.7354643 | H31: =IF(ISNA(G31),NA(),IF(G31>0,EXP(-1.085+0.9256*LN(G31))/G31,0)) -> 0.29019311 | I31: =IF(OR(ISNA(G31),ISNA(H31)),NA(),G31*H31) -> 2.2447785 | J31: =IF(OR(ISNA(G31),ISNA(I31)),NA(),G31+I31) -> 9.9802427 | K31: =Z31*0.47*(44/12) -> 17.199285 | Q31: =A31&"|"&B31 -> Cashew|30 | Y31: =Y30*(1-AB2) + MAX(0,J30-J31) -> 0 | Z31: =J31+Y31 -> 9.9802427
A32: Cashew | B32: 31 | C32: =INDEX($N$2:$N$6, MATCH(A32, $M$2:$M$6, 0)) -> 70 | D32: =IF(B32=1,INDEX($T$2:$T$6, MATCH(A32, $S$2:$S$6, 0)),INDEX($T$2:$T$6, MATCH(A32, $S$2:$S$6, 0))*POWER(INDEX($U$2:$U$6, MATCH(A32, $S$2:$S$6, 0)),MIN(B32-1,2))*POWER(INDEX($V$2:$V$6, MATCH(A32, $S$2:$S$6, 0)),MAX(MIN(B32-3,17),0))*POWER(INDEX($W$2:$W$6, MATCH(A32, $S$2:$S$6, 0)),MAX(B32-20,0))) -> 0.48317596 | E32: =C32*D32 -> 33.822317 | F32: =IFERROR(INDEX('3_GrowthInputs'!$F$2:$F$201, MATCH(Q32, '3_GrowthInputs'!$G$2:$G$201, 0)), NA()) -> 229.58908 | G32: =IF(OR(ISNA(E32),ISNA(F32)),NA(),E32*F32/1000) -> 7.7652348 | H32: =IF(ISNA(G32),NA(),IF(G32>0,EXP(-1.085+0.9256*LN(G32))/G32,0)) -> 0.29011019 | I32: =IF(OR(ISNA(G32),ISNA(H32)),NA(),G32*H32) -> 2.2527738 | J32: =IF(OR(ISNA(G32),ISNA(I32)),NA(),G32+I32) -> 10.018009 | K32: =Z32*0.47*(44/12) -> 17.264368 | Q32: =A32&"|"&B32 -> Cashew|31 | Y32: =Y31*(1-AB2) + MAX(0,J31-J32) -> 0 | Z32: =J32+Y32 -> 10.018009
A33: Cashew | B33: 32 | C33: =INDEX($N$2:$N$6, MATCH(A33, $M$2:$M$6, 0)) -> 70 | D33: =IF(B33=1,INDEX($T$2:$T$6, MATCH(A33, $S$2:$S$6, 0)),INDEX($T$2:$T$6, MATCH(A33, $S$2:$S$6, 0))*POWER(INDEX($U$2:$U$6, MATCH(A33, $S$2:$S$6, 0)),MIN(B33-1,2))*POWER(INDEX($V$2:$V$6, MATCH(A33, $S$2:$S$6, 0)),MAX(MIN(B33-3,17),0))*POWER(INDEX($W$2:$W$6, MATCH(A33, $S$2:$S$6, 0)),MAX(B33-20,0))) -> 0.47592832 | E33: =C33*D33 -> 33.314982 | F33: =IFERROR(INDEX('3_GrowthInputs'!$F$2:$F$201, MATCH(Q33, '3_GrowthInputs'!$G$2:$G$201, 0)), NA()) -> 233.20454 | G33: =IF(OR(ISNA(E33),ISNA(F33)),NA(),E33*F33/1000) -> 7.769205 | H33: =IF(ISNA(G33),NA(),IF(G33>0,EXP(-1.085+0.9256*LN(G33))/G33,0)) -> 0.29009916 | I33: =IF(OR(ISNA(G33),ISNA(H33)),NA(),G33*H33) -> 2.2538398 | J33: =IF(OR(ISNA(G33),ISNA(I33)),NA(),G33+I33) -> 10.023045 | K33: =Z33*0.47*(44/12) -> 17.273047 | Q33: =A33&"|"&B33 -> Cashew|32 | Y33: =Y32*(1-AB2) + MAX(0,J32-J33) -> 0 | Z33: =J33+Y33 -> 10.023045
A34: Cashew | B34: 33 | C34: =INDEX($N$2:$N$6, MATCH(A34, $M$2:$M$6, 0)) -> 70 | D34: =IF(B34=1,INDEX($T$2:$T$6, MATCH(A34, $S$2:$S$6, 0)),INDEX($T$2:$T$6, MATCH(A34, $S$2:$S$6, 0))*POWER(INDEX($U$2:$U$6, MATCH(A34, $S$2:$S$6, 0)),MIN(B34-1,2))*POWER(INDEX($V$2:$V$6, MATCH(A34, $S$2:$S$6, 0)),MAX(MIN(B34-3,17),0))*POWER(INDEX($W$2:$W$6, MATCH(A34, $S$2:$S$6, 0)),MAX(B34-20,0))) -> 0.4687894 | E34: =C34*D34 -> 32.815258 | F34: =IFERROR(INDEX('3_GrowthInputs'!$F$2:$F$201, MATCH(Q34, '3_GrowthInputs'!$G$2:$G$201, 0)), NA()) -> 236.25603 | G34: =IF(OR(ISNA(E34),ISNA(F34)),NA(),E34*F34/1000) -> 7.7528024 | H34: =IF(ISNA(G34),NA(),IF(G34>0,EXP(-1.085+0.9256*LN(G34))/G34,0)) -> 0.29014478 | I34: =IF(OR(ISNA(G34),ISNA(H34)),NA(),G34*H34) -> 2.2494351 | J34: =IF(OR(ISNA(G34),ISNA(I34)),NA(),G34+I34) -> 10.002238 | K34: =Z34*0.47*(44/12) -> 17.273047 | Q34: =A34&"|"&B34 -> Cashew|33 | Y34: =Y33*(1-AB2) + MAX(0,J33-J34) -> 0.020807336 | Z34: =J34+Y34 -> 10.023045
A35: Cashew | B35: 34 | C35: =INDEX($N$2:$N$6, MATCH(A35, $M$2:$M$6, 0)) -> 70 | D35: =IF(B35=1,INDEX($T$2:$T$6, MATCH(A35, $S$2:$S$6, 0)),INDEX($T$2:$T$6, MATCH(A35, $S$2:$S$6, 0))*POWER(INDEX($U$2:$U$6, MATCH(A35, $S$2:$S$6, 0)),MIN(B35-1,2))*POWER(INDEX($V$2:$V$6, MATCH(A35, $S$2:$S$6, 0)),MAX(MIN(B35-3,17),0))*POWER(INDEX($W$2:$W$6, MATCH(A35, $S$2:$S$6, 0)),MAX(B35-20,0))) -> 0.46175755 | E35: =C35*D35 -> 32.323029 | F35: =IFERROR(INDEX('3_GrowthInputs'!$F$2:$F$201, MATCH(Q35, '3_GrowthInputs'!$G$2:$G$201, 0)), NA()) -> 238.766 | G35: =IF(OR(ISNA(E35),ISNA(F35)),NA(),E35*F35/1000) -> 7.7176402 | H35: =IF(ISNA(G35),NA(),IF(G35>0,EXP(-1.085+0.9256*LN(G35))/G35,0)) -> 0.29024292 | I35: =IF(OR(ISNA(G35),ISNA(H35)),NA(),G35*H35) -> 2.2399905 | J35: =IF(OR(ISNA(G35),ISNA(I35)),NA(),G35+I35) -> 9.9576307 | K35: =Z35*0.47*(44/12) -> 17.269462 | Q35: =A35&"|"&B35 -> Cashew|34 | Y35: =Y34*(1-AB2) + MAX(0,J34-J35) -> 0.063333437 | Z35: =J35+Y35 -> 10.020964
A36: Cashew | B36: 35 | C36: =INDEX($N$2:$N$6, MATCH(A36, $M$2:$M$6, 0)) -> 70 | D36: =IF(B36=1,INDEX($T$2:$T$6, MATCH(A36, $S$2:$S$6, 0)),INDEX($T$2:$T$6, MATCH(A36, $S$2:$S$6, 0))*POWER(INDEX($U$2:$U$6, MATCH(A36, $S$2:$S$6, 0)),MIN(B36-1,2))*POWER(INDEX($V$2:$V$6, MATCH(A36, $S$2:$S$6, 0)),MAX(MIN(B36-3,17),0))*POWER(INDEX($W$2:$W$6, MATCH(A36, $S$2:$S$6, 0)),MAX(B36-20,0))) -> 0.45483119 | E36: =C36*D36 -> 31.838183 | F36: =IFERROR(INDEX('3_GrowthInputs'!$F$2:$F$201, MATCH(Q36, '3_GrowthInputs'!$G$2:$G$201, 0)), NA()) -> 240.87793 | G36: =IF(OR(ISNA(E36),ISNA(F36)),NA(),E36*F36/1000) -> 7.6691157 | H36: =IF(ISNA(G36),NA(),IF(G36>0,EXP(-1.085+0.9256*LN(G36))/G36,0)) -> 0.29037916 | I36: =IF(OR(ISNA(G36),ISNA(H36)),NA(),G36*H36) -> 2.2269513 | J36: =IF(OR(ISNA(G36),ISNA(I36)),NA(),G36+I36) -> 9.8960671 | K36: =Z36*0.47*(44/12) -> 17.258547 | Q36: =A36&"|"&B36 -> Cashew|35 | Y36: =Y35*(1-AB2) + MAX(0,J35-J36) -> 0.11856374 | Z36: =J36+Y36 -> 10.014631
A37: Cashew | B37: 36 | C37: =INDEX($N$2:$N$6, MATCH(A37, $M$2:$M$6, 0)) -> 70 | D37: =IF(B37=1,INDEX($T$2:$T$6, MATCH(A37, $S$2:$S$6, 0)),INDEX($T$2:$T$6, MATCH(A37, $S$2:$S$6, 0))*POWER(INDEX($U$2:$U$6, MATCH(A37, $S$2:$S$6, 0)),MIN(B37-1,2))*POWER(INDEX($V$2:$V$6, MATCH(A37, $S$2:$S$6, 0)),MAX(MIN(B37-3,17),0))*POWER(INDEX($W$2:$W$6, MATCH(A37, $S$2:$S$6, 0)),MAX(B37-20,0))) -> 0.44800872 | E37: =C37*D37 -> 31.360611 | F37: =IFERROR(INDEX('3_GrowthInputs'!$F$2:$F$201, MATCH(Q37, '3_GrowthInputs'!$G$2:$G$201, 0)), NA()) -> 242.64027 | G37: =IF(OR(ISNA(E37),ISNA(F37)),NA(),E37*F37/1000) -> 7.6093471 | H37: =IF(ISNA(G37),NA(),IF(G37>0,EXP(-1.085+0.9256*LN(G37))/G37,0)) -> 0.29054823 | I37: =IF(OR(ISNA(G37),ISNA(H37)),NA(),G37*H37) -> 2.2108824 | J37: =IF(OR(ISNA(G37),ISNA(I37)),NA(),G37+I37) -> 9.8202295 | K37: =Z37*0.47*(44/12) -> 17.238115 | Q37: =A37&"|"&B37 -> Cashew|36 | Y37: =Y36*(1-AB2) + MAX(0,J36-J37) -> 0.18254495 | Z37: =J37+Y37 -> 10.002774
A38: Cashew | B38: 37 | C38: =INDEX($N$2:$N$6, MATCH(A38, $M$2:$M$6, 0)) -> 70 | D38: =IF(B38=1,INDEX($T$2:$T$6, MATCH(A38, $S$2:$S$6, 0)),INDEX($T$2:$T$6, MATCH(A38, $S$2:$S$6, 0))*POWER(INDEX($U$2:$U$6, MATCH(A38, $S$2:$S$6, 0)),MIN(B38-1,2))*POWER(INDEX($V$2:$V$6, MATCH(A38, $S$2:$S$6, 0)),MAX(MIN(B38-3,17),0))*POWER(INDEX($W$2:$W$6, MATCH(A38, $S$2:$S$6, 0)),MAX(B38-20,0))) -> 0.44128859 | E38: =C38*D38 -> 30.890201 | F38: =IFERROR(INDEX('3_GrowthInputs'!$F$2:$F$201, MATCH(Q38, '3_GrowthInputs'!$G$2:$G$201, 0)), NA()) -> 244.08941 | G38: =IF(OR(ISNA(E38),ISNA(F38)),NA(),E38*F38/1000) -> 7.5399709 | H38: =IF(ISNA(G38),NA(),IF(G38>0,EXP(-1.085+0.9256*LN(G38))/G38,0)) -> 0.29074629 | I38: =IF(OR(ISNA(G38),ISNA(H38)),NA(),G38*H38) -> 2.1922186 | J38: =IF(OR(ISNA(G38),ISNA(I38)),NA(),G38+I38) -> 9.7321895 | K38: =Z38*0.47*(44/12) -> 17.206656 | Q38: =A38&"|"&B38 -> Cashew|37 | Y38: =Y37*(1-AB2) + MAX(0,J37-J38) -> 0.25233046 | Z38: =J38+Y38 -> 9.9845199
A39: Cashew | B39: 38 | C39: =INDEX($N$2:$N$6, MATCH(A39, $M$2:$M$6, 0)) -> 70 | D39: =IF(B39=1,INDEX($T$2:$T$6, MATCH(A39, $S$2:$S$6, 0)),INDEX($T$2:$T$6, MATCH(A39, $S$2:$S$6, 0))*POWER(INDEX($U$2:$U$6, MATCH(A39, $S$2:$S$6, 0)),MIN(B39-1,2))*POWER(INDEX($V$2:$V$6, MATCH(A39, $S$2:$S$6, 0)),MAX(MIN(B39-3,17),0))*POWER(INDEX($W$2:$W$6, MATCH(A39, $S$2:$S$6, 0)),MAX(B39-20,0))) -> 0.43466926 | E39: =C39*D39 -> 30.426848 | F39: =IFERROR(INDEX('3_GrowthInputs'!$F$2:$F$201, MATCH(Q39, '3_GrowthInputs'!$G$2:$G$201, 0)), NA()) -> 245.29557 | G39: =IF(OR(ISNA(E39),ISNA(F39)),NA(),E39*F39/1000) -> 7.4635712 | H39: =IF(ISNA(G39),NA(),IF(G39>0,EXP(-1.085+0.9256*LN(G39))/G39,0)) -> 0.29096668 | I39: =IF(OR(ISNA(G39),ISNA(H39)),NA(),G39*H39) -> 2.1716505 | J39: =IF(OR(ISNA(G39),ISNA(I39)),NA(),G39+I39) -> 9.6352217 | K39: =Z39*0.47*(44/12) -> 17.163171 | Q39: =A39&"|"&B39 -> Cashew|38 | Y39: =Y38*(1-AB2) + MAX(0,J38-J39) -> 0.32406518 | Z39: =J39+Y39 -> 9.9592869
A40: Cashew | B40: 39 | C40: =INDEX($N$2:$N$6, MATCH(A40, $M$2:$M$6, 0)) -> 70 | D40: =IF(B40=1,INDEX($T$2:$T$6, MATCH(A40, $S$2:$S$6, 0)),INDEX($T$2:$T$6, MATCH(A40, $S$2:$S$6, 0))*POWER(INDEX($U$2:$U$6, MATCH(A40, $S$2:$S$6, 0)),MIN(B40-1,2))*POWER(INDEX($V$2:$V$6, MATCH(A40, $S$2:$S$6, 0)),MAX(MIN(B40-3,17),0))*POWER(INDEX($W$2:$W$6, MATCH(A40, $S$2:$S$6, 0)),MAX(B40-20,0))) -> 0.42814922 | E40: =C40*D40 -> 29.970446 | F40: =IFERROR(INDEX('3_GrowthInputs'!$F$2:$F$201, MATCH(Q40, '3_GrowthInputs'!$G$2:$G$201, 0)), NA()) -> 246.29792 | G40: =IF(OR(ISNA(E40),ISNA(F40)),NA(),E40*F40/1000) -> 7.3816585 | H40: =IF(ISNA(G40),NA(),IF(G40>0,EXP(-1.085+0.9256*LN(G40))/G40,0)) -> 0.29120567 | I40: =IF(OR(ISNA(G40),ISNA(H40)),NA(),G40*H40) -> 2.1495808 | J40: =IF(OR(ISNA(G40),ISNA(I40)),NA(),G40+I40) -> 9.5312393 | K40: =Z40*0.47*(44/12) -> 17.107324 | Q40: =A40&"|"&B40 -> Cashew|39 | Y40: =Y39*(1-AB2) + MAX(0,J39-J40) -> 0.39564104 | Z40: =J40+Y40 -> 9.9268804
...

Sheet 5_Eq49_Output
A1: Eq49-ready: annual total tree CO2e stock and annual change | F1: Total agroforestry area (ha) | G1: 8000
A2: Year (t) | B2: Total tree CO2e stock (t CO2e) | C2: ΔCTREE,wp,t (t CO2e/yr) | D2: ΔCTREE,wp,t per ha (t CO2e/ha/yr) | F2: Total ERRs (t CO2e) | H2: Species | I2: Area_ha
A3: 1 | B3: ='4_BiomassPerHa'!$K$2*INDEX($I$3:$I$7,MATCH("Cashew",$H$3:$H$7,0))+'4_BiomassPerHa'!$K$42*INDEX($I$3:$I$7,MATCH("Dawadawa",$H$3:$H$7,0))+'4_BiomassPerHa'!$K$82*INDEX($I$3:$I$7,MATCH("Mango",$H$3:$H$7,0))+'4_BiomassPerHa'!$K$122*INDEX($I$3:$I$7,MATCH("Moringa",$H$3:$H$7,0))+'4_BiomassPerHa'!$K$162*INDEX($I$3:$I$7,MATCH("Shea",$H$3:$H$7,0)) -> 384.99197 | C3: =B3 -> 384.99197 | D3: =C3/G1 -> 0.048123997 | F3: =D3*$G$1 -> 384.99197 | H3: Cashew | I3: 4444.4444
A4: 2 | B4: ='4_BiomassPerHa'!$K$3*INDEX($I$3:$I$7,MATCH("Cashew",$H$3:$H$7,0))+'4_BiomassPerHa'!$K$43*INDEX($I$3:$I$7,MATCH("Dawadawa",$H$3:$H$7,0))+'4_BiomassPerHa'!$K$83*INDEX($I$3:$I$7,MATCH("Mango",$H$3:$H$7,0))+'4_BiomassPerHa'!$K$123*INDEX($I$3:$I$7,MATCH("Moringa",$H$3:$H$7,0))+'4_BiomassPerHa'!$K$163*INDEX($I$3:$I$7,MATCH("Shea",$H$3:$H$7,0)) -> 747.05794 | C4: =B4-B3 -> 362.06597 | D4: =C4/G1 -> 0.045258246 | F4: =D4*$G$1 -> 362.06597 | H4: Dawadawa | I4: 222.22222
A5: 3 | B5: ='4_BiomassPerHa'!$K$4*INDEX($I$3:$I$7,MATCH("Cashew",$H$3:$H$7,0))+'4_BiomassPerHa'!$K$44*INDEX($I$3:$I$7,MATCH("Dawadawa",$H$3:$H$7,0))+'4_BiomassPerHa'!$K$84*INDEX($I$3:$I$7,MATCH("Mango",$H$3:$H$7,0))+'4_BiomassPerHa'!$K$124*INDEX($I$3:$I$7,MATCH("Moringa",$H$3:$H$7,0))+'4_BiomassPerHa'!$K$164*INDEX($I$3:$I$7,MATCH("Shea",$H$3:$H$7,0)) -> 1241.8451 | C5: =B5-B4 -> 494.78713 | D5: =C5/G1 -> 0.061848391 | F5: =D5*$G$1 -> 494.78713 | H5: Mango | I5: 1111.1111
A6: 4 | B6: ='4_BiomassPerHa'!$K$5*INDEX($I$3:$I$7,MATCH("Cashew",$H$3:$H$7,0))+'4_BiomassPerHa'!$K$45*INDEX($I$3:$I$7,MATCH("Dawadawa",$H$3:$H$7,0))+'4_BiomassPerHa'!$K$85*INDEX($I$3:$I$7,MATCH("Mango",$H$3:$H$7,0))+'4_BiomassPerHa'!$K$125*INDEX($I$3:$I$7,MATCH("Moringa",$H$3:$H$7,0))+'4_BiomassPerHa'!$K$165*INDEX($I$3:$I$7,MATCH("Shea",$H$3:$H$7,0)) -> 2281.8468 | C6: =B6-B5 -> 1040.0017 | D6: =C6/G1 -> 0.13000021 | F6: =D6*$G$1 -> 1040.0017 | H6: Moringa | I6: 1111.1111
A7: 5 | B7: ='4_BiomassPerHa'!$K$6*INDEX($I$3:$I$7,MATCH("Cashew",$H$3:$H$7,0))+'4_BiomassPerHa'!$K$46*INDEX($I$3:$I$7,MATCH("Dawadawa",$H$3:$H$7,0))+'4_BiomassPerHa'!$K$86*INDEX($I$3:$I$7,MATCH("Mango",$H$3:$H$7,0))+'4_BiomassPerHa'!$K$126*INDEX($I$3:$I$7,MATCH("Moringa",$H$3:$H$7,0))+'4_BiomassPerHa'!$K$166*INDEX($I$3:$I$7,MATCH("Shea",$H$3:$H$7,0)) -> 4341.9347 | C7: =B7-B6 -> 2060.0879 | D7: =C7/G1 -> 0.25751098 | F7: =D7*$G$1 -> 2060.0879 | H7: Shea | I7: 1111.1111
A8: 6 | B8: ='4_BiomassPerHa'!$K$7*INDEX($I$3:$I$7,MATCH("Cashew",$H$3:$H$7,0))+'4_BiomassPerHa'!$K$47*INDEX($I$3:$I$7,MATCH("Dawadawa",$H$3:$H$7,0))+'4_BiomassPerHa'!$K$87*INDEX($I$3:$I$7,MATCH("Mango",$H$3:$H$7,0))+'4_BiomassPerHa'!$K$127*INDEX($I$3:$I$7,MATCH("Moringa",$H$3:$H$7,0))+'4_BiomassPerHa'!$K$167*INDEX($I$3:$I$7,MATCH("Shea",$H$3:$H$7,0)) -> 8191.7882 | C8: =B8-B7 -> 3849.8535 | D8: =C8/G1 -> 0.48123169 | F8: =D8*$G$1 -> 3849.8535
A9: 7 | B9: ='4_BiomassPerHa'!$K$8*INDEX($I$3:$I$7,MATCH("Cashew",$H$3:$H$7,0))+'4_BiomassPerHa'!$K$48*INDEX($I$3:$I$7,MATCH("Dawadawa",$H$3:$H$7,0))+'4_BiomassPerHa'!$K$88*INDEX($I$3:$I$7,MATCH("Mango",$H$3:$H$7,0))+'4_BiomassPerHa'!$K$128*INDEX($I$3:$I$7,MATCH("Moringa",$H$3:$H$7,0))+'4_BiomassPerHa'!$K$168*INDEX($I$3:$I$7,MATCH("Shea",$H$3:$H$7,0)) -> 14580.189 | C9: =B9-B8 -> 6388.4003 | D9: =C9/G1 -> 0.79855004 | F9: =D9*$G$1 -> 6388.4003
A10: 8 | B10: ='4_BiomassPerHa'!$K$9*INDEX($I$3:$I$7,MATCH("Cashew",$H$3:$H$7,0))+'4_BiomassPerHa'!$K$49*INDEX($I$3:$I$7,MATCH("Dawadawa",$H$3:$H$7,0))+'4_BiomassPerHa'!$K$89*INDEX($I$3:$I$7,MATCH("Mango",$H$3:$H$7,0))+'4_BiomassPerHa'!$K$129*INDEX($I$3:$I$7,MATCH("Moringa",$H$3:$H$7,0))+'4_BiomassPerHa'!$K$169*INDEX($I$3:$I$7,MATCH("Shea",$H$3:$H$7,0)) -> 23580.345 | C10: =B10-B9 -> 9000.1569 | D10: =C10/G1 -> 1.1250196 | F10: =D10*$G$1 -> 9000.1569
A11: 9 | B11: ='4_BiomassPerHa'!$K$10*INDEX($I$3:$I$7,MATCH("Cashew",$H$3:$H$7,0))+'4_BiomassPerHa'!$K$50*INDEX($I$3:$I$7,MATCH("Dawadawa",$H$3:$H$7,0))+'4_BiomassPerHa'!$K$90*INDEX($I$3:$I$7,MATCH("Mango",$H$3:$H$7,0))+'4_BiomassPerHa'!$K$130*INDEX($I$3:$I$7,MATCH("Moringa",$H$3:$H$7,0))+'4_BiomassPerHa'!$K$170*INDEX($I$3:$I$7,MATCH("Shea",$H$3:$H$7,0)) -> 34264.249 | C11: =B11-B10 -> 10683.904 | D11: =C11/G1 -> 1.335488 | F11: =D11*$G$1 -> 10683.904
A12: 10 | B12: ='4_BiomassPerHa'!$K$11*INDEX($I$3:$I$7,MATCH("Cashew",$H$3:$H$7,0))+'4_BiomassPerHa'!$K$51*INDEX($I$3:$I$7,MATCH("Dawadawa",$H$3:$H$7,0))+'4_BiomassPerHa'!$K$91*INDEX($I$3:$I$7,MATCH("Mango",$H$3:$H$7,0))+'4_BiomassPerHa'!$K$131*INDEX($I$3:$I$7,MATCH("Moringa",$H$3:$H$7,0))+'4_BiomassPerHa'!$K$171*INDEX($I$3:$I$7,MATCH("Shea",$H$3:$H$7,0)) -> 45390.938 | C12: =B12-B11 -> 11126.688 | D12: =C12/G1 -> 1.390836 | F12: =D12*$G$1 -> 11126.688
A13: 11 | B13: ='4_BiomassPerHa'!$K$12*INDEX($I$3:$I$7,MATCH("Cashew",$H$3:$H$7,0))+'4_BiomassPerHa'!$K$52*INDEX($I$3:$I$7,MATCH("Dawadawa",$H$3:$H$7,0))+'4_BiomassPerHa'!$K$92*INDEX($I$3:$I$7,MATCH("Mango",$H$3:$H$7,0))+'4_BiomassPerHa'!$K$132*INDEX($I$3:$I$7,MATCH("Moringa",$H$3:$H$7,0))+'4_BiomassPerHa'!$K$172*INDEX($I$3:$I$7,MATCH("Shea",$H$3:$H$7,0)) -> 56320.952 | C13: =B13-B12 -> 10930.015 | D13: =C13/G1 -> 1.3662518 | F13: =D13*$G$1 -> 10930.015
A14: 12 | B14: ='4_BiomassPerHa'!$K$13*INDEX($I$3:$I$7,MATCH("Cashew",$H$3:$H$7,0))+'4_BiomassPerHa'!$K$53*INDEX($I$3:$I$7,MATCH("Dawadawa",$H$3:$H$7,0))+'4_BiomassPerHa'!$K$93*INDEX($I$3:$I$7,MATCH("Mango",$H$3:$H$7,0))+'4_BiomassPerHa'!$K$133*INDEX($I$3:$I$7,MATCH("Moringa",$H$3:$H$7,0))+'4_BiomassPerHa'!$K$173*INDEX($I$3:$I$7,MATCH("Shea",$H$3:$H$7,0)) -> 67237.602 | C14: =B14-B13 -> 10916.649 | D14: =C14/G1 -> 1.3645812 | F14: =D14*$G$1 -> 10916.649
A15: 13 | B15: ='4_BiomassPerHa'!$K$14*INDEX($I$3:$I$7,MATCH("Cashew",$H$3:$H$7,0))+'4_BiomassPerHa'!$K$54*INDEX($I$3:$I$7,MATCH("Dawadawa",$H$3:$H$7,0))+'4_BiomassPerHa'!$K$94*INDEX($I$3:$I$7,MATCH("Mango",$H$3:$H$7,0))+'4_BiomassPerHa'!$K$134*INDEX($I$3:$I$7,MATCH("Moringa",$H$3:$H$7,0))+'4_BiomassPerHa'!$K$174*INDEX($I$3:$I$7,MATCH("Shea",$H$3:$H$7,0)) -> 78755.074 | C15: =B15-B14 -> 11517.473 | D15: =C15/G1 -> 1.4396841 | F15: =D15*$G$1 -> 11517.473
A16: 14 | B16: ='4_BiomassPerHa'!$K$15*INDEX($I$3:$I$7,MATCH("Cashew",$H$3:$H$7,0))+'4_BiomassPerHa'!$K$55*INDEX($I$3:$I$7,MATCH("Dawadawa",$H$3:$H$7,0))+'4_BiomassPerHa'!$K$95*INDEX($I$3:$I$7,MATCH("Mango",$H$3:$H$7,0))+'4_BiomassPerHa'!$K$135*INDEX($I$3:$I$7,MATCH("Moringa",$H$3:$H$7,0))+'4_BiomassPerHa'!$K$175*INDEX($I$3:$I$7,MATCH("Shea",$H$3:$H$7,0)) -> 91527.727 | C16: =B16-B15 -> 12772.652 | D16: =C16/G1 -> 1.5965815 | F16: =D16*$G$1 -> 12772.652
A17: 15 | B17: ='4_BiomassPerHa'!$K$16*INDEX($I$3:$I$7,MATCH("Cashew",$H$3:$H$7,0))+'4_BiomassPerHa'!$K$56*INDEX($I$3:$I$7,MATCH("Dawadawa",$H$3:$H$7,0))+'4_BiomassPerHa'!$K$96*INDEX($I$3:$I$7,MATCH("Mango",$H$3:$H$7,0))+'4_BiomassPerHa'!$K$136*INDEX($I$3:$I$7,MATCH("Moringa",$H$3:$H$7,0))+'4_BiomassPerHa'!$K$176*INDEX($I$3:$I$7,MATCH("Shea",$H$3:$H$7,0)) -> 106083.64 | C17: =B17-B16 -> 14555.913 | D17: =C17/G1 -> 1.8194892 | F17: =D17*$G$1 -> 14555.913
A18: 16 | B18: ='4_BiomassPerHa'!$K$17*INDEX($I$3:$I$7,MATCH("Cashew",$H$3:$H$7,0))+'4_BiomassPerHa'!$K$57*INDEX($I$3:$I$7,MATCH("Dawadawa",$H$3:$H$7,0))+'4_BiomassPerHa'!$K$97*INDEX($I$3:$I$7,MATCH("Mango",$H$3:$H$7,0))+'4_BiomassPerHa'!$K$137*INDEX($I$3:$I$7,MATCH("Moringa",$H$3:$H$7,0))+'4_BiomassPerHa'!$K$177*INDEX($I$3:$I$7,MATCH("Shea",$H$3:$H$7,0)) -> 122907.34 | C18: =B18-B17 -> 16823.699 | D18: =C18/G1 -> 2.1029624 | F18: =D18*$G$1 -> 16823.699
A19: 17 | B19: ='4_BiomassPerHa'!$K$18*INDEX($I$3:$I$7,MATCH("Cashew",$H$3:$H$7,0))+'4_BiomassPerHa'!$K$58*INDEX($I$3:$I$7,MATCH("Dawadawa",$H$3:$H$7,0))+'4_BiomassPerHa'!$K$98*INDEX($I$3:$I$7,MATCH("Mango",$H$3:$H$7,0))+'4_BiomassPerHa'!$K$138*INDEX($I$3:$I$7,MATCH("Moringa",$H$3:$H$7,0))+'4_BiomassPerHa'!$K$178*INDEX($I$3:$I$7,MATCH("Shea",$H$3:$H$7,0)) -> 142227.59 | C19: =B19-B18 -> 19320.256 | D19: =C19/G1 -> 2.415032 | F19: =D19*$G$1 -> 19320.256
A20: 18 | B20: ='4_BiomassPerHa'!$K$19*INDEX($I$3:$I$7,MATCH("Cashew",$H$3:$H$7,0))+'4_BiomassPerHa'!$K$59*INDEX($I$3:$I$7,MATCH("Dawadawa",$H$3:$H$7,0))+'4_BiomassPerHa'!$K$99*INDEX($I$3:$I$7,MATCH("Mango",$H$3:$H$7,0))+'4_BiomassPerHa'!$K$139*INDEX($I$3:$I$7,MATCH("Moringa",$H$3:$H$7,0))+'4_BiomassPerHa'!$K$179*INDEX($I$3:$I$7,MATCH("Shea",$H$3:$H$7,0)) -> 164015.27 | C20: =B20-B19 -> 21787.679 | D20: =C20/G1 -> 2.7234599 | F20: =D20*$G$1 -> 21787.679
A21: 19 | B21: ='4_BiomassPerHa'!$K$20*INDEX($I$3:$I$7,MATCH("Cashew",$H$3:$H$7,0))+'4_BiomassPerHa'!$K$60*INDEX($I$3:$I$7,MATCH("Dawadawa",$H$3:$H$7,0))+'4_BiomassPerHa'!$K$100*INDEX($I$3:$I$7,MATCH("Mango",$H$3:$H$7,0))+'4_BiomassPerHa'!$K$140*INDEX($I$3:$I$7,MATCH("Moringa",$H$3:$H$7,0))+'4_BiomassPerHa'!$K$180*INDEX($I$3:$I$7,MATCH("Shea",$H$3:$H$7,0)) -> 188151.76 | C21: =B21-B20 -> 24136.489 | D21: =C21/G1 -> 3.0170611 | F21: =D21*$G$1 -> 24136.489
A22: 20 | B22: ='4_BiomassPerHa'!$K$21*INDEX($I$3:$I$7,MATCH("Cashew",$H$3:$H$7,0))+'4_BiomassPerHa'!$K$61*INDEX($I$3:$I$7,MATCH("Dawadawa",$H$3:$H$7,0))+'4_BiomassPerHa'!$K$101*INDEX($I$3:$I$7,MATCH("Mango",$H$3:$H$7,0))+'4_BiomassPerHa'!$K$141*INDEX($I$3:$I$7,MATCH("Moringa",$H$3:$H$7,0))+'4_BiomassPerHa'!$K$181*INDEX($I$3:$I$7,MATCH("Shea",$H$3:$H$7,0)) -> 214464.54 | C22: =B22-B21 -> 26312.782 | D22: =C22/G1 -> 3.2890978 | F22: =D22*$G$1 -> 26312.782
A23: 21 | B23: ='4_BiomassPerHa'!$K$22*INDEX($I$3:$I$7,MATCH("Cashew",$H$3:$H$7,0))+'4_BiomassPerHa'!$K$62*INDEX($I$3:$I$7,MATCH("Dawadawa",$H$3:$H$7,0))+'4_BiomassPerHa'!$K$102*INDEX($I$3:$I$7,MATCH("Mango",$H$3:$H$7,0))+'4_BiomassPerHa'!$K$142*INDEX($I$3:$I$7,MATCH("Moringa",$H$3:$H$7,0))+'4_BiomassPerHa'!$K$182*INDEX($I$3:$I$7,MATCH("Shea",$H$3:$H$7,0)) -> 241691.87 | C23: =B23-B22 -> 27227.323 | D23: =C23/G1 -> 3.4034153 | F23: =D23*$G$1 -> 27227.323
A24: 22 | B24: ='4_BiomassPerHa'!$K$23*INDEX($I$3:$I$7,MATCH("Cashew",$H$3:$H$7,0))+'4_BiomassPerHa'!$K$63*INDEX($I$3:$I$7,MATCH("Dawadawa",$H$3:$H$7,0))+'4_BiomassPerHa'!$K$103*INDEX($I$3:$I$7,MATCH("Mango",$H$3:$H$7,0))+'4_BiomassPerHa'!$K$143*INDEX($I$3:$I$7,MATCH("Moringa",$H$3:$H$7,0))+'4_BiomassPerHa'!$K$183*INDEX($I$3:$I$7,MATCH("Shea",$H$3:$H$7,0)) -> 270183.59 | C24: =B24-B23 -> 28491.721 | D24: =C24/G1 -> 3.5614652 | F24: =D24*$G$1 -> 28491.721
A25: 23 | B25: ='4_BiomassPerHa'!$K$24*INDEX($I$3:$I$7,MATCH("Cashew",$H$3:$H$7,0))+'4_BiomassPerHa'!$K$64*INDEX($I$3:$I$7,MATCH("Dawadawa",$H$3:$H$7,0))+'4_BiomassPerHa'!$K$104*INDEX($I$3:$I$7,MATCH("Mango",$H$3:$H$7,0))+'4_BiomassPerHa'!$K$144*INDEX($I$3:$I$7,MATCH("Moringa",$H$3:$H$7,0))+'4_BiomassPerHa'!$K$184*INDEX($I$3:$I$7,MATCH("Shea",$H$3:$H$7,0)) -> 299570.36 | C25: =B25-B24 -> 29386.768 | D25: =C25/G1 -> 3.673346 | F25: =D25*$G$1 -> 29386.768
A26: 24 | B26: ='4_BiomassPerHa'!$K$25*INDEX($I$3:$I$7,MATCH("Cashew",$H$3:$H$7,0))+'4_BiomassPerHa'!$K$65*INDEX($I$3:$I$7,MATCH("Dawadawa",$H$3:$H$7,0))+'4_BiomassPerHa'!$K$105*INDEX($I$3:$I$7,MATCH("Mango",$H$3:$H$7,0))+'4_BiomassPerHa'!$K$145*INDEX($I$3:$I$7,MATCH("Moringa",$H$3:$H$7,0))+'4_BiomassPerHa'!$K$185*INDEX($I$3:$I$7,MATCH("Shea",$H$3:$H$7,0)) -> 329433.51 | C26: =B26-B25 -> 29863.152 | D26: =C26/G1 -> 3.7328941 | F26: =D26*$G$1 -> 29863.152
